2022-05-30 11:17:59,683 ERROR scheduler Exception in Enqueue Events for Site website
Traceback (most recent call last):
  File "apps/frappe/frappe/utils/scheduler.py", line 76, in enqueue_events_for_site
    if is_scheduler_inactive():
  File "apps/frappe/frappe/utils/scheduler.py", line 113, in is_scheduler_inactive
    if is_scheduler_disabled():
  File "apps/frappe/frappe/utils/scheduler.py", line 125, in is_scheduler_disabled
    frappe.db.get_single_value("System Settings", "enable_scheduler")
  File "apps/frappe/frappe/database/database.py", line 671, in get_single_value
    val = self.query.get_sql(
  File "apps/frappe/frappe/query_builder/utils.py", line 71, in execute_query
    return frappe.db.sql(query, params, *args, **kwargs)  # nosemgrep
  File "apps/frappe/frappe/database/database.py", line 145, in sql
    self.connect()
  File "apps/frappe/frappe/database/database.py", line 76, in connect
    self._conn = self.get_connection()
  File "apps/frappe/frappe/database/mariadb/database.py", line 79, in get_connection
    conn = pymysql.connect(
  File "env/lib/python3.8/site-packages/pymysql/connections.py", line 353, in __init__
    self.connect()
  File "env/lib/python3.8/site-packages/pymysql/connections.py", line 633, in connect
    self._request_authentication()
  File "env/lib/python3.8/site-packages/pymysql/connections.py", line 907, in _request_authentication
    auth_packet = self._read_packet()
  File "env/lib/python3.8/site-packages/pymysql/connections.py", line 725, in _read_packet
    packet.raise_for_error()
  File "env/lib/python3.8/site-packages/pymysql/protocol.py", line 221, in raise_for_error
    err.raise_mysql_exception(self._data)
  File "env/lib/python3.8/site-packages/pymysql/err.py", line 143, in raise_mysql_exception
    raise errorclass(errno, errval)
pymysql.err.OperationalError: (1698, "Access denied for user '_b03d59da10ef7e85'@'localhost'")

2022-05-30 11:18:59,951 ERROR scheduler Exception in Enqueue Events for Site website
Traceback (most recent call last):
  File "apps/frappe/frappe/utils/scheduler.py", line 76, in enqueue_events_for_site
    if is_scheduler_inactive():
  File "apps/frappe/frappe/utils/scheduler.py", line 113, in is_scheduler_inactive
    if is_scheduler_disabled():
  File "apps/frappe/frappe/utils/scheduler.py", line 125, in is_scheduler_disabled
    frappe.db.get_single_value("System Settings", "enable_scheduler")
  File "apps/frappe/frappe/database/database.py", line 671, in get_single_value
    val = self.query.get_sql(
  File "apps/frappe/frappe/query_builder/utils.py", line 71, in execute_query
    return frappe.db.sql(query, params, *args, **kwargs)  # nosemgrep
  File "apps/frappe/frappe/database/database.py", line 145, in sql
    self.connect()
  File "apps/frappe/frappe/database/database.py", line 76, in connect
    self._conn = self.get_connection()
  File "apps/frappe/frappe/database/mariadb/database.py", line 79, in get_connection
    conn = pymysql.connect(
  File "env/lib/python3.8/site-packages/pymysql/connections.py", line 353, in __init__
    self.connect()
  File "env/lib/python3.8/site-packages/pymysql/connections.py", line 633, in connect
    self._request_authentication()
  File "env/lib/python3.8/site-packages/pymysql/connections.py", line 907, in _request_authentication
    auth_packet = self._read_packet()
  File "env/lib/python3.8/site-packages/pymysql/connections.py", line 725, in _read_packet
    packet.raise_for_error()
  File "env/lib/python3.8/site-packages/pymysql/protocol.py", line 221, in raise_for_error
    err.raise_mysql_exception(self._data)
  File "env/lib/python3.8/site-packages/pymysql/err.py", line 143, in raise_mysql_exception
    raise errorclass(errno, errval)
pymysql.err.OperationalError: (1698, "Access denied for user '_b03d59da10ef7e85'@'localhost'")

2022-05-30 11:20:00,282 ERROR scheduler Exception in Enqueue Events for Site website
Traceback (most recent call last):
  File "apps/frappe/frappe/utils/scheduler.py", line 76, in enqueue_events_for_site
    if is_scheduler_inactive():
  File "apps/frappe/frappe/utils/scheduler.py", line 113, in is_scheduler_inactive
    if is_scheduler_disabled():
  File "apps/frappe/frappe/utils/scheduler.py", line 125, in is_scheduler_disabled
    frappe.db.get_single_value("System Settings", "enable_scheduler")
  File "apps/frappe/frappe/database/database.py", line 671, in get_single_value
    val = self.query.get_sql(
  File "apps/frappe/frappe/query_builder/utils.py", line 71, in execute_query
    return frappe.db.sql(query, params, *args, **kwargs)  # nosemgrep
  File "apps/frappe/frappe/database/database.py", line 145, in sql
    self.connect()
  File "apps/frappe/frappe/database/database.py", line 76, in connect
    self._conn = self.get_connection()
  File "apps/frappe/frappe/database/mariadb/database.py", line 79, in get_connection
    conn = pymysql.connect(
  File "env/lib/python3.8/site-packages/pymysql/connections.py", line 353, in __init__
    self.connect()
  File "env/lib/python3.8/site-packages/pymysql/connections.py", line 633, in connect
    self._request_authentication()
  File "env/lib/python3.8/site-packages/pymysql/connections.py", line 907, in _request_authentication
    auth_packet = self._read_packet()
  File "env/lib/python3.8/site-packages/pymysql/connections.py", line 725, in _read_packet
    packet.raise_for_error()
  File "env/lib/python3.8/site-packages/pymysql/protocol.py", line 221, in raise_for_error
    err.raise_mysql_exception(self._data)
  File "env/lib/python3.8/site-packages/pymysql/err.py", line 143, in raise_mysql_exception
    raise errorclass(errno, errval)
pymysql.err.OperationalError: (1698, "Access denied for user '_b03d59da10ef7e85'@'localhost'")

2022-05-30 11:20:00,285 INFO scheduler Scheduled Job Start: frappe.monitor.flush for library.test
2022-05-30 11:20:00,565 INFO scheduler Scheduled Job Complete: frappe.monitor.flush for library.test
2022-05-30 11:20:00,676 INFO scheduler Scheduled Job Start: frappe.utils.global_search.sync_global_search for library.test
2022-05-30 11:20:00,880 INFO scheduler Scheduled Job Complete: frappe.utils.global_search.sync_global_search for library.test
2022-05-30 11:20:00,967 INFO scheduler Scheduled Job Start: frappe.integrations.doctype.razorpay_settings.razorpay_settings.capture_payment for library.test
2022-05-30 11:20:01,230 INFO scheduler Scheduled Job Complete: frappe.integrations.doctype.razorpay_settings.razorpay_settings.capture_payment for library.test
2022-05-30 11:20:01,318 INFO scheduler Scheduled Job Start: frappe.email.doctype.email_account.email_account.notify_unreplied for library.test
2022-05-30 11:20:01,597 INFO scheduler Scheduled Job Complete: frappe.email.doctype.email_account.email_account.notify_unreplied for library.test
2022-05-30 11:20:01,683 INFO scheduler Scheduled Job Start: frappe.email.doctype.email_account.email_account.pull for library.test
2022-05-30 11:20:01,981 INFO scheduler Scheduled Job Complete: frappe.email.doctype.email_account.email_account.pull for library.test
2022-05-30 11:20:02,068 INFO scheduler Scheduled Job Start: frappe.email.queue.flush for library.test
2022-05-30 11:20:02,300 INFO scheduler Scheduled Job Complete: frappe.email.queue.flush for library.test
2022-05-30 11:21:00,544 ERROR scheduler Exception in Enqueue Events for Site website
Traceback (most recent call last):
  File "apps/frappe/frappe/utils/scheduler.py", line 76, in enqueue_events_for_site
    if is_scheduler_inactive():
  File "apps/frappe/frappe/utils/scheduler.py", line 113, in is_scheduler_inactive
    if is_scheduler_disabled():
  File "apps/frappe/frappe/utils/scheduler.py", line 125, in is_scheduler_disabled
    frappe.db.get_single_value("System Settings", "enable_scheduler")
  File "apps/frappe/frappe/database/database.py", line 671, in get_single_value
    val = self.query.get_sql(
  File "apps/frappe/frappe/query_builder/utils.py", line 71, in execute_query
    return frappe.db.sql(query, params, *args, **kwargs)  # nosemgrep
  File "apps/frappe/frappe/database/database.py", line 145, in sql
    self.connect()
  File "apps/frappe/frappe/database/database.py", line 76, in connect
    self._conn = self.get_connection()
  File "apps/frappe/frappe/database/mariadb/database.py", line 79, in get_connection
    conn = pymysql.connect(
  File "env/lib/python3.8/site-packages/pymysql/connections.py", line 353, in __init__
    self.connect()
  File "env/lib/python3.8/site-packages/pymysql/connections.py", line 633, in connect
    self._request_authentication()
  File "env/lib/python3.8/site-packages/pymysql/connections.py", line 907, in _request_authentication
    auth_packet = self._read_packet()
  File "env/lib/python3.8/site-packages/pymysql/connections.py", line 725, in _read_packet
    packet.raise_for_error()
  File "env/lib/python3.8/site-packages/pymysql/protocol.py", line 221, in raise_for_error
    err.raise_mysql_exception(self._data)
  File "env/lib/python3.8/site-packages/pymysql/err.py", line 143, in raise_mysql_exception
    raise errorclass(errno, errval)
pymysql.err.OperationalError: (1698, "Access denied for user '_b03d59da10ef7e85'@'localhost'")

2022-05-30 11:22:00,808 ERROR scheduler Exception in Enqueue Events for Site website
Traceback (most recent call last):
  File "apps/frappe/frappe/utils/scheduler.py", line 76, in enqueue_events_for_site
    if is_scheduler_inactive():
  File "apps/frappe/frappe/utils/scheduler.py", line 113, in is_scheduler_inactive
    if is_scheduler_disabled():
  File "apps/frappe/frappe/utils/scheduler.py", line 125, in is_scheduler_disabled
    frappe.db.get_single_value("System Settings", "enable_scheduler")
  File "apps/frappe/frappe/database/database.py", line 671, in get_single_value
    val = self.query.get_sql(
  File "apps/frappe/frappe/query_builder/utils.py", line 71, in execute_query
    return frappe.db.sql(query, params, *args, **kwargs)  # nosemgrep
  File "apps/frappe/frappe/database/database.py", line 145, in sql
    self.connect()
  File "apps/frappe/frappe/database/database.py", line 76, in connect
    self._conn = self.get_connection()
  File "apps/frappe/frappe/database/mariadb/database.py", line 79, in get_connection
    conn = pymysql.connect(
  File "env/lib/python3.8/site-packages/pymysql/connections.py", line 353, in __init__
    self.connect()
  File "env/lib/python3.8/site-packages/pymysql/connections.py", line 633, in connect
    self._request_authentication()
  File "env/lib/python3.8/site-packages/pymysql/connections.py", line 907, in _request_authentication
    auth_packet = self._read_packet()
  File "env/lib/python3.8/site-packages/pymysql/connections.py", line 725, in _read_packet
    packet.raise_for_error()
  File "env/lib/python3.8/site-packages/pymysql/protocol.py", line 221, in raise_for_error
    err.raise_mysql_exception(self._data)
  File "env/lib/python3.8/site-packages/pymysql/err.py", line 143, in raise_mysql_exception
    raise errorclass(errno, errval)
pymysql.err.OperationalError: (1698, "Access denied for user '_b03d59da10ef7e85'@'localhost'")

2022-05-30 11:23:01,071 ERROR scheduler Exception in Enqueue Events for Site website
Traceback (most recent call last):
  File "apps/frappe/frappe/utils/scheduler.py", line 76, in enqueue_events_for_site
    if is_scheduler_inactive():
  File "apps/frappe/frappe/utils/scheduler.py", line 113, in is_scheduler_inactive
    if is_scheduler_disabled():
  File "apps/frappe/frappe/utils/scheduler.py", line 125, in is_scheduler_disabled
    frappe.db.get_single_value("System Settings", "enable_scheduler")
  File "apps/frappe/frappe/database/database.py", line 671, in get_single_value
    val = self.query.get_sql(
  File "apps/frappe/frappe/query_builder/utils.py", line 71, in execute_query
    return frappe.db.sql(query, params, *args, **kwargs)  # nosemgrep
  File "apps/frappe/frappe/database/database.py", line 145, in sql
    self.connect()
  File "apps/frappe/frappe/database/database.py", line 76, in connect
    self._conn = self.get_connection()
  File "apps/frappe/frappe/database/mariadb/database.py", line 79, in get_connection
    conn = pymysql.connect(
  File "env/lib/python3.8/site-packages/pymysql/connections.py", line 353, in __init__
    self.connect()
  File "env/lib/python3.8/site-packages/pymysql/connections.py", line 633, in connect
    self._request_authentication()
  File "env/lib/python3.8/site-packages/pymysql/connections.py", line 907, in _request_authentication
    auth_packet = self._read_packet()
  File "env/lib/python3.8/site-packages/pymysql/connections.py", line 725, in _read_packet
    packet.raise_for_error()
  File "env/lib/python3.8/site-packages/pymysql/protocol.py", line 221, in raise_for_error
    err.raise_mysql_exception(self._data)
  File "env/lib/python3.8/site-packages/pymysql/err.py", line 143, in raise_mysql_exception
    raise errorclass(errno, errval)
pymysql.err.OperationalError: (1698, "Access denied for user '_b03d59da10ef7e85'@'localhost'")

2022-05-30 11:24:01,409 ERROR scheduler Exception in Enqueue Events for Site website
Traceback (most recent call last):
  File "apps/frappe/frappe/utils/scheduler.py", line 76, in enqueue_events_for_site
    if is_scheduler_inactive():
  File "apps/frappe/frappe/utils/scheduler.py", line 113, in is_scheduler_inactive
    if is_scheduler_disabled():
  File "apps/frappe/frappe/utils/scheduler.py", line 125, in is_scheduler_disabled
    frappe.db.get_single_value("System Settings", "enable_scheduler")
  File "apps/frappe/frappe/database/database.py", line 671, in get_single_value
    val = self.query.get_sql(
  File "apps/frappe/frappe/query_builder/utils.py", line 71, in execute_query
    return frappe.db.sql(query, params, *args, **kwargs)  # nosemgrep
  File "apps/frappe/frappe/database/database.py", line 145, in sql
    self.connect()
  File "apps/frappe/frappe/database/database.py", line 76, in connect
    self._conn = self.get_connection()
  File "apps/frappe/frappe/database/mariadb/database.py", line 79, in get_connection
    conn = pymysql.connect(
  File "env/lib/python3.8/site-packages/pymysql/connections.py", line 353, in __init__
    self.connect()
  File "env/lib/python3.8/site-packages/pymysql/connections.py", line 633, in connect
    self._request_authentication()
  File "env/lib/python3.8/site-packages/pymysql/connections.py", line 907, in _request_authentication
    auth_packet = self._read_packet()
  File "env/lib/python3.8/site-packages/pymysql/connections.py", line 725, in _read_packet
    packet.raise_for_error()
  File "env/lib/python3.8/site-packages/pymysql/protocol.py", line 221, in raise_for_error
    err.raise_mysql_exception(self._data)
  File "env/lib/python3.8/site-packages/pymysql/err.py", line 143, in raise_mysql_exception
    raise errorclass(errno, errval)
pymysql.err.OperationalError: (1698, "Access denied for user '_b03d59da10ef7e85'@'localhost'")

2022-05-30 11:24:01,415 INFO scheduler Scheduled Job Start: frappe.monitor.flush for library.test
2022-05-30 11:24:01,708 INFO scheduler Scheduled Job Complete: frappe.monitor.flush for library.test
2022-05-30 11:24:01,824 INFO scheduler Scheduled Job Start: frappe.utils.global_search.sync_global_search for library.test
2022-05-30 11:24:02,020 INFO scheduler Scheduled Job Complete: frappe.utils.global_search.sync_global_search for library.test
2022-05-30 11:24:02,127 INFO scheduler Scheduled Job Start: frappe.integrations.doctype.razorpay_settings.razorpay_settings.capture_payment for library.test
2022-05-30 11:24:02,493 INFO scheduler Scheduled Job Complete: frappe.integrations.doctype.razorpay_settings.razorpay_settings.capture_payment for library.test
2022-05-30 11:24:02,582 INFO scheduler Scheduled Job Start: frappe.email.doctype.email_account.email_account.notify_unreplied for library.test
2022-05-30 11:24:02,858 INFO scheduler Scheduled Job Complete: frappe.email.doctype.email_account.email_account.notify_unreplied for library.test
2022-05-30 11:24:02,947 INFO scheduler Scheduled Job Start: frappe.email.doctype.email_account.email_account.pull for library.test
2022-05-30 11:24:03,247 INFO scheduler Scheduled Job Complete: frappe.email.doctype.email_account.email_account.pull for library.test
2022-05-30 11:24:03,336 INFO scheduler Scheduled Job Start: frappe.email.queue.flush for library.test
2022-05-30 11:24:03,609 INFO scheduler Scheduled Job Complete: frappe.email.queue.flush for library.test
2022-05-30 11:25:01,691 ERROR scheduler Exception in Enqueue Events for Site website
Traceback (most recent call last):
  File "apps/frappe/frappe/utils/scheduler.py", line 76, in enqueue_events_for_site
    if is_scheduler_inactive():
  File "apps/frappe/frappe/utils/scheduler.py", line 113, in is_scheduler_inactive
    if is_scheduler_disabled():
  File "apps/frappe/frappe/utils/scheduler.py", line 125, in is_scheduler_disabled
    frappe.db.get_single_value("System Settings", "enable_scheduler")
  File "apps/frappe/frappe/database/database.py", line 671, in get_single_value
    val = self.query.get_sql(
  File "apps/frappe/frappe/query_builder/utils.py", line 71, in execute_query
    return frappe.db.sql(query, params, *args, **kwargs)  # nosemgrep
  File "apps/frappe/frappe/database/database.py", line 145, in sql
    self.connect()
  File "apps/frappe/frappe/database/database.py", line 76, in connect
    self._conn = self.get_connection()
  File "apps/frappe/frappe/database/mariadb/database.py", line 79, in get_connection
    conn = pymysql.connect(
  File "env/lib/python3.8/site-packages/pymysql/connections.py", line 353, in __init__
    self.connect()
  File "env/lib/python3.8/site-packages/pymysql/connections.py", line 633, in connect
    self._request_authentication()
  File "env/lib/python3.8/site-packages/pymysql/connections.py", line 907, in _request_authentication
    auth_packet = self._read_packet()
  File "env/lib/python3.8/site-packages/pymysql/connections.py", line 725, in _read_packet
    packet.raise_for_error()
  File "env/lib/python3.8/site-packages/pymysql/protocol.py", line 221, in raise_for_error
    err.raise_mysql_exception(self._data)
  File "env/lib/python3.8/site-packages/pymysql/err.py", line 143, in raise_mysql_exception
    raise errorclass(errno, errval)
pymysql.err.OperationalError: (1698, "Access denied for user '_b03d59da10ef7e85'@'localhost'")

2022-05-30 11:26:02,019 ERROR scheduler Exception in Enqueue Events for Site website
Traceback (most recent call last):
  File "apps/frappe/frappe/utils/scheduler.py", line 76, in enqueue_events_for_site
    if is_scheduler_inactive():
  File "apps/frappe/frappe/utils/scheduler.py", line 113, in is_scheduler_inactive
    if is_scheduler_disabled():
  File "apps/frappe/frappe/utils/scheduler.py", line 125, in is_scheduler_disabled
    frappe.db.get_single_value("System Settings", "enable_scheduler")
  File "apps/frappe/frappe/database/database.py", line 671, in get_single_value
    val = self.query.get_sql(
  File "apps/frappe/frappe/query_builder/utils.py", line 71, in execute_query
    return frappe.db.sql(query, params, *args, **kwargs)  # nosemgrep
  File "apps/frappe/frappe/database/database.py", line 145, in sql
    self.connect()
  File "apps/frappe/frappe/database/database.py", line 76, in connect
    self._conn = self.get_connection()
  File "apps/frappe/frappe/database/mariadb/database.py", line 79, in get_connection
    conn = pymysql.connect(
  File "env/lib/python3.8/site-packages/pymysql/connections.py", line 353, in __init__
    self.connect()
  File "env/lib/python3.8/site-packages/pymysql/connections.py", line 633, in connect
    self._request_authentication()
  File "env/lib/python3.8/site-packages/pymysql/connections.py", line 907, in _request_authentication
    auth_packet = self._read_packet()
  File "env/lib/python3.8/site-packages/pymysql/connections.py", line 725, in _read_packet
    packet.raise_for_error()
  File "env/lib/python3.8/site-packages/pymysql/protocol.py", line 221, in raise_for_error
    err.raise_mysql_exception(self._data)
  File "env/lib/python3.8/site-packages/pymysql/err.py", line 143, in raise_mysql_exception
    raise errorclass(errno, errval)
pymysql.err.OperationalError: (1698, "Access denied for user '_b03d59da10ef7e85'@'localhost'")

2022-05-30 11:27:02,300 ERROR scheduler Exception in Enqueue Events for Site website
Traceback (most recent call last):
  File "apps/frappe/frappe/utils/scheduler.py", line 76, in enqueue_events_for_site
    if is_scheduler_inactive():
  File "apps/frappe/frappe/utils/scheduler.py", line 113, in is_scheduler_inactive
    if is_scheduler_disabled():
  File "apps/frappe/frappe/utils/scheduler.py", line 125, in is_scheduler_disabled
    frappe.db.get_single_value("System Settings", "enable_scheduler")
  File "apps/frappe/frappe/database/database.py", line 671, in get_single_value
    val = self.query.get_sql(
  File "apps/frappe/frappe/query_builder/utils.py", line 71, in execute_query
    return frappe.db.sql(query, params, *args, **kwargs)  # nosemgrep
  File "apps/frappe/frappe/database/database.py", line 145, in sql
    self.connect()
  File "apps/frappe/frappe/database/database.py", line 76, in connect
    self._conn = self.get_connection()
  File "apps/frappe/frappe/database/mariadb/database.py", line 79, in get_connection
    conn = pymysql.connect(
  File "env/lib/python3.8/site-packages/pymysql/connections.py", line 353, in __init__
    self.connect()
  File "env/lib/python3.8/site-packages/pymysql/connections.py", line 633, in connect
    self._request_authentication()
  File "env/lib/python3.8/site-packages/pymysql/connections.py", line 907, in _request_authentication
    auth_packet = self._read_packet()
  File "env/lib/python3.8/site-packages/pymysql/connections.py", line 725, in _read_packet
    packet.raise_for_error()
  File "env/lib/python3.8/site-packages/pymysql/protocol.py", line 221, in raise_for_error
    err.raise_mysql_exception(self._data)
  File "env/lib/python3.8/site-packages/pymysql/err.py", line 143, in raise_mysql_exception
    raise errorclass(errno, errval)
pymysql.err.OperationalError: (1698, "Access denied for user '_b03d59da10ef7e85'@'localhost'")

2022-05-30 11:28:02,641 ERROR scheduler Exception in Enqueue Events for Site website
Traceback (most recent call last):
  File "apps/frappe/frappe/utils/scheduler.py", line 76, in enqueue_events_for_site
    if is_scheduler_inactive():
  File "apps/frappe/frappe/utils/scheduler.py", line 113, in is_scheduler_inactive
    if is_scheduler_disabled():
  File "apps/frappe/frappe/utils/scheduler.py", line 125, in is_scheduler_disabled
    frappe.db.get_single_value("System Settings", "enable_scheduler")
  File "apps/frappe/frappe/database/database.py", line 671, in get_single_value
    val = self.query.get_sql(
  File "apps/frappe/frappe/query_builder/utils.py", line 71, in execute_query
    return frappe.db.sql(query, params, *args, **kwargs)  # nosemgrep
  File "apps/frappe/frappe/database/database.py", line 145, in sql
    self.connect()
  File "apps/frappe/frappe/database/database.py", line 76, in connect
    self._conn = self.get_connection()
  File "apps/frappe/frappe/database/mariadb/database.py", line 79, in get_connection
    conn = pymysql.connect(
  File "env/lib/python3.8/site-packages/pymysql/connections.py", line 353, in __init__
    self.connect()
  File "env/lib/python3.8/site-packages/pymysql/connections.py", line 633, in connect
    self._request_authentication()
  File "env/lib/python3.8/site-packages/pymysql/connections.py", line 907, in _request_authentication
    auth_packet = self._read_packet()
  File "env/lib/python3.8/site-packages/pymysql/connections.py", line 725, in _read_packet
    packet.raise_for_error()
  File "env/lib/python3.8/site-packages/pymysql/protocol.py", line 221, in raise_for_error
    err.raise_mysql_exception(self._data)
  File "env/lib/python3.8/site-packages/pymysql/err.py", line 143, in raise_mysql_exception
    raise errorclass(errno, errval)
pymysql.err.OperationalError: (1698, "Access denied for user '_b03d59da10ef7e85'@'localhost'")

2022-05-30 11:28:02,657 INFO scheduler Scheduled Job Start: frappe.monitor.flush for library.test
2022-05-30 11:28:02,925 INFO scheduler Scheduled Job Complete: frappe.monitor.flush for library.test
2022-05-30 11:28:03,033 INFO scheduler Scheduled Job Start: frappe.utils.global_search.sync_global_search for library.test
2022-05-30 11:28:03,228 INFO scheduler Scheduled Job Complete: frappe.utils.global_search.sync_global_search for library.test
2022-05-30 11:28:03,315 INFO scheduler Scheduled Job Start: frappe.integrations.doctype.razorpay_settings.razorpay_settings.capture_payment for library.test
2022-05-30 11:28:03,566 INFO scheduler Scheduled Job Complete: frappe.integrations.doctype.razorpay_settings.razorpay_settings.capture_payment for library.test
2022-05-30 11:28:03,654 INFO scheduler Scheduled Job Start: frappe.email.doctype.email_account.email_account.notify_unreplied for library.test
2022-05-30 11:28:03,923 INFO scheduler Scheduled Job Complete: frappe.email.doctype.email_account.email_account.notify_unreplied for library.test
2022-05-30 11:28:04,012 INFO scheduler Scheduled Job Start: frappe.email.doctype.email_account.email_account.pull for library.test
2022-05-30 11:28:04,455 INFO scheduler Scheduled Job Complete: frappe.email.doctype.email_account.email_account.pull for library.test
2022-05-30 11:28:04,544 INFO scheduler Scheduled Job Start: frappe.email.queue.flush for library.test
2022-05-30 11:28:04,816 INFO scheduler Scheduled Job Complete: frappe.email.queue.flush for library.test
2022-05-30 11:29:02,905 ERROR scheduler Exception in Enqueue Events for Site website
Traceback (most recent call last):
  File "apps/frappe/frappe/utils/scheduler.py", line 76, in enqueue_events_for_site
    if is_scheduler_inactive():
  File "apps/frappe/frappe/utils/scheduler.py", line 113, in is_scheduler_inactive
    if is_scheduler_disabled():
  File "apps/frappe/frappe/utils/scheduler.py", line 125, in is_scheduler_disabled
    frappe.db.get_single_value("System Settings", "enable_scheduler")
  File "apps/frappe/frappe/database/database.py", line 671, in get_single_value
    val = self.query.get_sql(
  File "apps/frappe/frappe/query_builder/utils.py", line 71, in execute_query
    return frappe.db.sql(query, params, *args, **kwargs)  # nosemgrep
  File "apps/frappe/frappe/database/database.py", line 145, in sql
    self.connect()
  File "apps/frappe/frappe/database/database.py", line 76, in connect
    self._conn = self.get_connection()
  File "apps/frappe/frappe/database/mariadb/database.py", line 79, in get_connection
    conn = pymysql.connect(
  File "env/lib/python3.8/site-packages/pymysql/connections.py", line 353, in __init__
    self.connect()
  File "env/lib/python3.8/site-packages/pymysql/connections.py", line 633, in connect
    self._request_authentication()
  File "env/lib/python3.8/site-packages/pymysql/connections.py", line 907, in _request_authentication
    auth_packet = self._read_packet()
  File "env/lib/python3.8/site-packages/pymysql/connections.py", line 725, in _read_packet
    packet.raise_for_error()
  File "env/lib/python3.8/site-packages/pymysql/protocol.py", line 221, in raise_for_error
    err.raise_mysql_exception(self._data)
  File "env/lib/python3.8/site-packages/pymysql/err.py", line 143, in raise_mysql_exception
    raise errorclass(errno, errval)
pymysql.err.OperationalError: (1698, "Access denied for user '_b03d59da10ef7e85'@'localhost'")

2022-05-30 11:30:03,226 ERROR scheduler Exception in Enqueue Events for Site website
Traceback (most recent call last):
  File "apps/frappe/frappe/utils/scheduler.py", line 76, in enqueue_events_for_site
    if is_scheduler_inactive():
  File "apps/frappe/frappe/utils/scheduler.py", line 113, in is_scheduler_inactive
    if is_scheduler_disabled():
  File "apps/frappe/frappe/utils/scheduler.py", line 125, in is_scheduler_disabled
    frappe.db.get_single_value("System Settings", "enable_scheduler")
  File "apps/frappe/frappe/database/database.py", line 671, in get_single_value
    val = self.query.get_sql(
  File "apps/frappe/frappe/query_builder/utils.py", line 71, in execute_query
    return frappe.db.sql(query, params, *args, **kwargs)  # nosemgrep
  File "apps/frappe/frappe/database/database.py", line 145, in sql
    self.connect()
  File "apps/frappe/frappe/database/database.py", line 76, in connect
    self._conn = self.get_connection()
  File "apps/frappe/frappe/database/mariadb/database.py", line 79, in get_connection
    conn = pymysql.connect(
  File "env/lib/python3.8/site-packages/pymysql/connections.py", line 353, in __init__
    self.connect()
  File "env/lib/python3.8/site-packages/pymysql/connections.py", line 633, in connect
    self._request_authentication()
  File "env/lib/python3.8/site-packages/pymysql/connections.py", line 907, in _request_authentication
    auth_packet = self._read_packet()
  File "env/lib/python3.8/site-packages/pymysql/connections.py", line 725, in _read_packet
    packet.raise_for_error()
  File "env/lib/python3.8/site-packages/pymysql/protocol.py", line 221, in raise_for_error
    err.raise_mysql_exception(self._data)
  File "env/lib/python3.8/site-packages/pymysql/err.py", line 143, in raise_mysql_exception
    raise errorclass(errno, errval)
pymysql.err.OperationalError: (1698, "Access denied for user '_b03d59da10ef7e85'@'localhost'")

2022-05-30 11:30:03,278 INFO scheduler Scheduled Job Start: frappe.twofactor.delete_all_barcodes_for_users for library.test
2022-05-30 11:30:03,700 INFO scheduler Scheduled Job Complete: frappe.twofactor.delete_all_barcodes_for_users for library.test
2022-05-30 11:30:03,822 INFO scheduler Scheduled Job Start: frappe.website.doctype.web_page.web_page.check_publish_status for library.test
2022-05-30 11:30:04,318 INFO scheduler Scheduled Job Complete: frappe.website.doctype.web_page.web_page.check_publish_status for library.test
2022-05-30 11:30:04,605 INFO scheduler Scheduled Job Start: frappe.oauth.delete_oauth2_data for library.test
2022-05-30 11:30:04,975 INFO scheduler Scheduled Job Complete: frappe.oauth.delete_oauth2_data for library.test
2022-05-30 11:31:03,498 ERROR scheduler Exception in Enqueue Events for Site website
Traceback (most recent call last):
  File "apps/frappe/frappe/utils/scheduler.py", line 76, in enqueue_events_for_site
    if is_scheduler_inactive():
  File "apps/frappe/frappe/utils/scheduler.py", line 113, in is_scheduler_inactive
    if is_scheduler_disabled():
  File "apps/frappe/frappe/utils/scheduler.py", line 125, in is_scheduler_disabled
    frappe.db.get_single_value("System Settings", "enable_scheduler")
  File "apps/frappe/frappe/database/database.py", line 671, in get_single_value
    val = self.query.get_sql(
  File "apps/frappe/frappe/query_builder/utils.py", line 71, in execute_query
    return frappe.db.sql(query, params, *args, **kwargs)  # nosemgrep
  File "apps/frappe/frappe/database/database.py", line 145, in sql
    self.connect()
  File "apps/frappe/frappe/database/database.py", line 76, in connect
    self._conn = self.get_connection()
  File "apps/frappe/frappe/database/mariadb/database.py", line 79, in get_connection
    conn = pymysql.connect(
  File "env/lib/python3.8/site-packages/pymysql/connections.py", line 353, in __init__
    self.connect()
  File "env/lib/python3.8/site-packages/pymysql/connections.py", line 633, in connect
    self._request_authentication()
  File "env/lib/python3.8/site-packages/pymysql/connections.py", line 907, in _request_authentication
    auth_packet = self._read_packet()
  File "env/lib/python3.8/site-packages/pymysql/connections.py", line 725, in _read_packet
    packet.raise_for_error()
  File "env/lib/python3.8/site-packages/pymysql/protocol.py", line 221, in raise_for_error
    err.raise_mysql_exception(self._data)
  File "env/lib/python3.8/site-packages/pymysql/err.py", line 143, in raise_mysql_exception
    raise errorclass(errno, errval)
pymysql.err.OperationalError: (1698, "Access denied for user '_b03d59da10ef7e85'@'localhost'")

2022-05-30 11:32:03,857 ERROR scheduler Exception in Enqueue Events for Site website
Traceback (most recent call last):
  File "apps/frappe/frappe/utils/scheduler.py", line 76, in enqueue_events_for_site
    if is_scheduler_inactive():
  File "apps/frappe/frappe/utils/scheduler.py", line 113, in is_scheduler_inactive
    if is_scheduler_disabled():
  File "apps/frappe/frappe/utils/scheduler.py", line 125, in is_scheduler_disabled
    frappe.db.get_single_value("System Settings", "enable_scheduler")
  File "apps/frappe/frappe/database/database.py", line 671, in get_single_value
    val = self.query.get_sql(
  File "apps/frappe/frappe/query_builder/utils.py", line 71, in execute_query
    return frappe.db.sql(query, params, *args, **kwargs)  # nosemgrep
  File "apps/frappe/frappe/database/database.py", line 145, in sql
    self.connect()
  File "apps/frappe/frappe/database/database.py", line 76, in connect
    self._conn = self.get_connection()
  File "apps/frappe/frappe/database/mariadb/database.py", line 79, in get_connection
    conn = pymysql.connect(
  File "env/lib/python3.8/site-packages/pymysql/connections.py", line 353, in __init__
    self.connect()
  File "env/lib/python3.8/site-packages/pymysql/connections.py", line 633, in connect
    self._request_authentication()
  File "env/lib/python3.8/site-packages/pymysql/connections.py", line 907, in _request_authentication
    auth_packet = self._read_packet()
  File "env/lib/python3.8/site-packages/pymysql/connections.py", line 725, in _read_packet
    packet.raise_for_error()
  File "env/lib/python3.8/site-packages/pymysql/protocol.py", line 221, in raise_for_error
    err.raise_mysql_exception(self._data)
  File "env/lib/python3.8/site-packages/pymysql/err.py", line 143, in raise_mysql_exception
    raise errorclass(errno, errval)
pymysql.err.OperationalError: (1698, "Access denied for user '_b03d59da10ef7e85'@'localhost'")

2022-05-30 11:32:03,864 INFO scheduler Scheduled Job Start: frappe.monitor.flush for library.test
2022-05-30 11:32:04,158 INFO scheduler Scheduled Job Complete: frappe.monitor.flush for library.test
2022-05-30 11:32:04,276 INFO scheduler Scheduled Job Start: frappe.utils.global_search.sync_global_search for library.test
2022-05-30 11:32:04,473 INFO scheduler Scheduled Job Complete: frappe.utils.global_search.sync_global_search for library.test
2022-05-30 11:32:04,574 INFO scheduler Scheduled Job Start: frappe.integrations.doctype.razorpay_settings.razorpay_settings.capture_payment for library.test
2022-05-30 11:32:04,821 INFO scheduler Scheduled Job Complete: frappe.integrations.doctype.razorpay_settings.razorpay_settings.capture_payment for library.test
2022-05-30 11:32:04,909 INFO scheduler Scheduled Job Start: frappe.email.doctype.email_account.email_account.notify_unreplied for library.test
2022-05-30 11:32:05,193 INFO scheduler Scheduled Job Complete: frappe.email.doctype.email_account.email_account.notify_unreplied for library.test
2022-05-30 11:32:05,281 INFO scheduler Scheduled Job Start: frappe.email.doctype.email_account.email_account.pull for library.test
2022-05-30 11:32:05,582 INFO scheduler Scheduled Job Complete: frappe.email.doctype.email_account.email_account.pull for library.test
2022-05-30 11:32:05,671 INFO scheduler Scheduled Job Start: frappe.email.queue.flush for library.test
2022-05-30 11:32:05,907 INFO scheduler Scheduled Job Complete: frappe.email.queue.flush for library.test
2022-05-30 11:33:04,124 ERROR scheduler Exception in Enqueue Events for Site website
Traceback (most recent call last):
  File "apps/frappe/frappe/utils/scheduler.py", line 76, in enqueue_events_for_site
    if is_scheduler_inactive():
  File "apps/frappe/frappe/utils/scheduler.py", line 113, in is_scheduler_inactive
    if is_scheduler_disabled():
  File "apps/frappe/frappe/utils/scheduler.py", line 125, in is_scheduler_disabled
    frappe.db.get_single_value("System Settings", "enable_scheduler")
  File "apps/frappe/frappe/database/database.py", line 671, in get_single_value
    val = self.query.get_sql(
  File "apps/frappe/frappe/query_builder/utils.py", line 71, in execute_query
    return frappe.db.sql(query, params, *args, **kwargs)  # nosemgrep
  File "apps/frappe/frappe/database/database.py", line 145, in sql
    self.connect()
  File "apps/frappe/frappe/database/database.py", line 76, in connect
    self._conn = self.get_connection()
  File "apps/frappe/frappe/database/mariadb/database.py", line 79, in get_connection
    conn = pymysql.connect(
  File "env/lib/python3.8/site-packages/pymysql/connections.py", line 353, in __init__
    self.connect()
  File "env/lib/python3.8/site-packages/pymysql/connections.py", line 633, in connect
    self._request_authentication()
  File "env/lib/python3.8/site-packages/pymysql/connections.py", line 907, in _request_authentication
    auth_packet = self._read_packet()
  File "env/lib/python3.8/site-packages/pymysql/connections.py", line 725, in _read_packet
    packet.raise_for_error()
  File "env/lib/python3.8/site-packages/pymysql/protocol.py", line 221, in raise_for_error
    err.raise_mysql_exception(self._data)
  File "env/lib/python3.8/site-packages/pymysql/err.py", line 143, in raise_mysql_exception
    raise errorclass(errno, errval)
pymysql.err.OperationalError: (1698, "Access denied for user '_b03d59da10ef7e85'@'localhost'")

2022-05-30 11:34:04,381 ERROR scheduler Exception in Enqueue Events for Site website
Traceback (most recent call last):
  File "apps/frappe/frappe/utils/scheduler.py", line 76, in enqueue_events_for_site
    if is_scheduler_inactive():
  File "apps/frappe/frappe/utils/scheduler.py", line 113, in is_scheduler_inactive
    if is_scheduler_disabled():
  File "apps/frappe/frappe/utils/scheduler.py", line 125, in is_scheduler_disabled
    frappe.db.get_single_value("System Settings", "enable_scheduler")
  File "apps/frappe/frappe/database/database.py", line 671, in get_single_value
    val = self.query.get_sql(
  File "apps/frappe/frappe/query_builder/utils.py", line 71, in execute_query
    return frappe.db.sql(query, params, *args, **kwargs)  # nosemgrep
  File "apps/frappe/frappe/database/database.py", line 145, in sql
    self.connect()
  File "apps/frappe/frappe/database/database.py", line 76, in connect
    self._conn = self.get_connection()
  File "apps/frappe/frappe/database/mariadb/database.py", line 79, in get_connection
    conn = pymysql.connect(
  File "env/lib/python3.8/site-packages/pymysql/connections.py", line 353, in __init__
    self.connect()
  File "env/lib/python3.8/site-packages/pymysql/connections.py", line 633, in connect
    self._request_authentication()
  File "env/lib/python3.8/site-packages/pymysql/connections.py", line 907, in _request_authentication
    auth_packet = self._read_packet()
  File "env/lib/python3.8/site-packages/pymysql/connections.py", line 725, in _read_packet
    packet.raise_for_error()
  File "env/lib/python3.8/site-packages/pymysql/protocol.py", line 221, in raise_for_error
    err.raise_mysql_exception(self._data)
  File "env/lib/python3.8/site-packages/pymysql/err.py", line 143, in raise_mysql_exception
    raise errorclass(errno, errval)
pymysql.err.OperationalError: (1698, "Access denied for user '_b03d59da10ef7e85'@'localhost'")

2022-05-30 11:35:04,579 ERROR scheduler Exception in Enqueue Events for Site website
Traceback (most recent call last):
  File "apps/frappe/frappe/utils/scheduler.py", line 76, in enqueue_events_for_site
    if is_scheduler_inactive():
  File "apps/frappe/frappe/utils/scheduler.py", line 113, in is_scheduler_inactive
    if is_scheduler_disabled():
  File "apps/frappe/frappe/utils/scheduler.py", line 125, in is_scheduler_disabled
    frappe.db.get_single_value("System Settings", "enable_scheduler")
  File "apps/frappe/frappe/database/database.py", line 671, in get_single_value
    val = self.query.get_sql(
  File "apps/frappe/frappe/query_builder/utils.py", line 71, in execute_query
    return frappe.db.sql(query, params, *args, **kwargs)  # nosemgrep
  File "apps/frappe/frappe/database/database.py", line 145, in sql
    self.connect()
  File "apps/frappe/frappe/database/database.py", line 76, in connect
    self._conn = self.get_connection()
  File "apps/frappe/frappe/database/mariadb/database.py", line 79, in get_connection
    conn = pymysql.connect(
  File "env/lib/python3.8/site-packages/pymysql/connections.py", line 353, in __init__
    self.connect()
  File "env/lib/python3.8/site-packages/pymysql/connections.py", line 633, in connect
    self._request_authentication()
  File "env/lib/python3.8/site-packages/pymysql/connections.py", line 907, in _request_authentication
    auth_packet = self._read_packet()
  File "env/lib/python3.8/site-packages/pymysql/connections.py", line 725, in _read_packet
    packet.raise_for_error()
  File "env/lib/python3.8/site-packages/pymysql/protocol.py", line 221, in raise_for_error
    err.raise_mysql_exception(self._data)
  File "env/lib/python3.8/site-packages/pymysql/err.py", line 143, in raise_mysql_exception
    raise errorclass(errno, errval)
pymysql.err.OperationalError: (1698, "Access denied for user '_b03d59da10ef7e85'@'localhost'")

2022-05-30 11:36:04,805 ERROR scheduler Exception in Enqueue Events for Site website
Traceback (most recent call last):
  File "apps/frappe/frappe/utils/scheduler.py", line 76, in enqueue_events_for_site
    if is_scheduler_inactive():
  File "apps/frappe/frappe/utils/scheduler.py", line 113, in is_scheduler_inactive
    if is_scheduler_disabled():
  File "apps/frappe/frappe/utils/scheduler.py", line 125, in is_scheduler_disabled
    frappe.db.get_single_value("System Settings", "enable_scheduler")
  File "apps/frappe/frappe/database/database.py", line 671, in get_single_value
    val = self.query.get_sql(
  File "apps/frappe/frappe/query_builder/utils.py", line 71, in execute_query
    return frappe.db.sql(query, params, *args, **kwargs)  # nosemgrep
  File "apps/frappe/frappe/database/database.py", line 145, in sql
    self.connect()
  File "apps/frappe/frappe/database/database.py", line 76, in connect
    self._conn = self.get_connection()
  File "apps/frappe/frappe/database/mariadb/database.py", line 79, in get_connection
    conn = pymysql.connect(
  File "env/lib/python3.8/site-packages/pymysql/connections.py", line 353, in __init__
    self.connect()
  File "env/lib/python3.8/site-packages/pymysql/connections.py", line 633, in connect
    self._request_authentication()
  File "env/lib/python3.8/site-packages/pymysql/connections.py", line 907, in _request_authentication
    auth_packet = self._read_packet()
  File "env/lib/python3.8/site-packages/pymysql/connections.py", line 725, in _read_packet
    packet.raise_for_error()
  File "env/lib/python3.8/site-packages/pymysql/protocol.py", line 221, in raise_for_error
    err.raise_mysql_exception(self._data)
  File "env/lib/python3.8/site-packages/pymysql/err.py", line 143, in raise_mysql_exception
    raise errorclass(errno, errval)
pymysql.err.OperationalError: (1698, "Access denied for user '_b03d59da10ef7e85'@'localhost'")

2022-05-30 11:36:04,807 INFO scheduler Scheduled Job Start: frappe.monitor.flush for library.test
2022-05-30 11:36:04,993 INFO scheduler Scheduled Job Complete: frappe.monitor.flush for library.test
2022-05-30 11:36:05,086 INFO scheduler Scheduled Job Start: frappe.utils.global_search.sync_global_search for library.test
2022-05-30 11:36:05,194 INFO scheduler Scheduled Job Complete: frappe.utils.global_search.sync_global_search for library.test
2022-05-30 11:36:05,271 INFO scheduler Scheduled Job Start: frappe.integrations.doctype.razorpay_settings.razorpay_settings.capture_payment for library.test
2022-05-30 11:36:05,397 INFO scheduler Scheduled Job Complete: frappe.integrations.doctype.razorpay_settings.razorpay_settings.capture_payment for library.test
2022-05-30 11:36:05,439 INFO scheduler Scheduled Job Start: frappe.email.doctype.email_account.email_account.notify_unreplied for library.test
2022-05-30 11:36:05,577 INFO scheduler Scheduled Job Complete: frappe.email.doctype.email_account.email_account.notify_unreplied for library.test
2022-05-30 11:36:05,622 INFO scheduler Scheduled Job Start: frappe.email.doctype.email_account.email_account.pull for library.test
2022-05-30 11:36:05,781 INFO scheduler Scheduled Job Complete: frappe.email.doctype.email_account.email_account.pull for library.test
2022-05-30 11:36:05,824 INFO scheduler Scheduled Job Start: frappe.email.queue.flush for library.test
2022-05-30 11:36:06,130 INFO scheduler Scheduled Job Complete: frappe.email.queue.flush for library.test
2022-05-30 11:37:04,988 ERROR scheduler Exception in Enqueue Events for Site website
Traceback (most recent call last):
  File "apps/frappe/frappe/utils/scheduler.py", line 76, in enqueue_events_for_site
    if is_scheduler_inactive():
  File "apps/frappe/frappe/utils/scheduler.py", line 113, in is_scheduler_inactive
    if is_scheduler_disabled():
  File "apps/frappe/frappe/utils/scheduler.py", line 125, in is_scheduler_disabled
    frappe.db.get_single_value("System Settings", "enable_scheduler")
  File "apps/frappe/frappe/database/database.py", line 671, in get_single_value
    val = self.query.get_sql(
  File "apps/frappe/frappe/query_builder/utils.py", line 71, in execute_query
    return frappe.db.sql(query, params, *args, **kwargs)  # nosemgrep
  File "apps/frappe/frappe/database/database.py", line 145, in sql
    self.connect()
  File "apps/frappe/frappe/database/database.py", line 76, in connect
    self._conn = self.get_connection()
  File "apps/frappe/frappe/database/mariadb/database.py", line 79, in get_connection
    conn = pymysql.connect(
  File "env/lib/python3.8/site-packages/pymysql/connections.py", line 353, in __init__
    self.connect()
  File "env/lib/python3.8/site-packages/pymysql/connections.py", line 633, in connect
    self._request_authentication()
  File "env/lib/python3.8/site-packages/pymysql/connections.py", line 907, in _request_authentication
    auth_packet = self._read_packet()
  File "env/lib/python3.8/site-packages/pymysql/connections.py", line 725, in _read_packet
    packet.raise_for_error()
  File "env/lib/python3.8/site-packages/pymysql/protocol.py", line 221, in raise_for_error
    err.raise_mysql_exception(self._data)
  File "env/lib/python3.8/site-packages/pymysql/err.py", line 143, in raise_mysql_exception
    raise errorclass(errno, errval)
pymysql.err.OperationalError: (1698, "Access denied for user '_b03d59da10ef7e85'@'localhost'")

2022-05-30 11:38:05,177 ERROR scheduler Exception in Enqueue Events for Site website
Traceback (most recent call last):
  File "apps/frappe/frappe/utils/scheduler.py", line 76, in enqueue_events_for_site
    if is_scheduler_inactive():
  File "apps/frappe/frappe/utils/scheduler.py", line 113, in is_scheduler_inactive
    if is_scheduler_disabled():
  File "apps/frappe/frappe/utils/scheduler.py", line 125, in is_scheduler_disabled
    frappe.db.get_single_value("System Settings", "enable_scheduler")
  File "apps/frappe/frappe/database/database.py", line 671, in get_single_value
    val = self.query.get_sql(
  File "apps/frappe/frappe/query_builder/utils.py", line 71, in execute_query
    return frappe.db.sql(query, params, *args, **kwargs)  # nosemgrep
  File "apps/frappe/frappe/database/database.py", line 145, in sql
    self.connect()
  File "apps/frappe/frappe/database/database.py", line 76, in connect
    self._conn = self.get_connection()
  File "apps/frappe/frappe/database/mariadb/database.py", line 79, in get_connection
    conn = pymysql.connect(
  File "env/lib/python3.8/site-packages/pymysql/connections.py", line 353, in __init__
    self.connect()
  File "env/lib/python3.8/site-packages/pymysql/connections.py", line 633, in connect
    self._request_authentication()
  File "env/lib/python3.8/site-packages/pymysql/connections.py", line 907, in _request_authentication
    auth_packet = self._read_packet()
  File "env/lib/python3.8/site-packages/pymysql/connections.py", line 725, in _read_packet
    packet.raise_for_error()
  File "env/lib/python3.8/site-packages/pymysql/protocol.py", line 221, in raise_for_error
    err.raise_mysql_exception(self._data)
  File "env/lib/python3.8/site-packages/pymysql/err.py", line 143, in raise_mysql_exception
    raise errorclass(errno, errval)
pymysql.err.OperationalError: (1698, "Access denied for user '_b03d59da10ef7e85'@'localhost'")

2022-05-30 11:39:05,363 ERROR scheduler Exception in Enqueue Events for Site website
Traceback (most recent call last):
  File "apps/frappe/frappe/utils/scheduler.py", line 76, in enqueue_events_for_site
    if is_scheduler_inactive():
  File "apps/frappe/frappe/utils/scheduler.py", line 113, in is_scheduler_inactive
    if is_scheduler_disabled():
  File "apps/frappe/frappe/utils/scheduler.py", line 125, in is_scheduler_disabled
    frappe.db.get_single_value("System Settings", "enable_scheduler")
  File "apps/frappe/frappe/database/database.py", line 671, in get_single_value
    val = self.query.get_sql(
  File "apps/frappe/frappe/query_builder/utils.py", line 71, in execute_query
    return frappe.db.sql(query, params, *args, **kwargs)  # nosemgrep
  File "apps/frappe/frappe/database/database.py", line 145, in sql
    self.connect()
  File "apps/frappe/frappe/database/database.py", line 76, in connect
    self._conn = self.get_connection()
  File "apps/frappe/frappe/database/mariadb/database.py", line 79, in get_connection
    conn = pymysql.connect(
  File "env/lib/python3.8/site-packages/pymysql/connections.py", line 353, in __init__
    self.connect()
  File "env/lib/python3.8/site-packages/pymysql/connections.py", line 633, in connect
    self._request_authentication()
  File "env/lib/python3.8/site-packages/pymysql/connections.py", line 907, in _request_authentication
    auth_packet = self._read_packet()
  File "env/lib/python3.8/site-packages/pymysql/connections.py", line 725, in _read_packet
    packet.raise_for_error()
  File "env/lib/python3.8/site-packages/pymysql/protocol.py", line 221, in raise_for_error
    err.raise_mysql_exception(self._data)
  File "env/lib/python3.8/site-packages/pymysql/err.py", line 143, in raise_mysql_exception
    raise errorclass(errno, errval)
pymysql.err.OperationalError: (1698, "Access denied for user '_b03d59da10ef7e85'@'localhost'")

2022-05-30 11:40:05,594 ERROR scheduler Exception in Enqueue Events for Site website
Traceback (most recent call last):
  File "apps/frappe/frappe/utils/scheduler.py", line 76, in enqueue_events_for_site
    if is_scheduler_inactive():
  File "apps/frappe/frappe/utils/scheduler.py", line 113, in is_scheduler_inactive
    if is_scheduler_disabled():
  File "apps/frappe/frappe/utils/scheduler.py", line 125, in is_scheduler_disabled
    frappe.db.get_single_value("System Settings", "enable_scheduler")
  File "apps/frappe/frappe/database/database.py", line 671, in get_single_value
    val = self.query.get_sql(
  File "apps/frappe/frappe/query_builder/utils.py", line 71, in execute_query
    return frappe.db.sql(query, params, *args, **kwargs)  # nosemgrep
  File "apps/frappe/frappe/database/database.py", line 145, in sql
    self.connect()
  File "apps/frappe/frappe/database/database.py", line 76, in connect
    self._conn = self.get_connection()
  File "apps/frappe/frappe/database/mariadb/database.py", line 79, in get_connection
    conn = pymysql.connect(
  File "env/lib/python3.8/site-packages/pymysql/connections.py", line 353, in __init__
    self.connect()
  File "env/lib/python3.8/site-packages/pymysql/connections.py", line 633, in connect
    self._request_authentication()
  File "env/lib/python3.8/site-packages/pymysql/connections.py", line 907, in _request_authentication
    auth_packet = self._read_packet()
  File "env/lib/python3.8/site-packages/pymysql/connections.py", line 725, in _read_packet
    packet.raise_for_error()
  File "env/lib/python3.8/site-packages/pymysql/protocol.py", line 221, in raise_for_error
    err.raise_mysql_exception(self._data)
  File "env/lib/python3.8/site-packages/pymysql/err.py", line 143, in raise_mysql_exception
    raise errorclass(errno, errval)
pymysql.err.OperationalError: (1698, "Access denied for user '_b03d59da10ef7e85'@'localhost'")

2022-05-30 11:41:05,785 ERROR scheduler Exception in Enqueue Events for Site website
Traceback (most recent call last):
  File "apps/frappe/frappe/utils/scheduler.py", line 76, in enqueue_events_for_site
    if is_scheduler_inactive():
  File "apps/frappe/frappe/utils/scheduler.py", line 113, in is_scheduler_inactive
    if is_scheduler_disabled():
  File "apps/frappe/frappe/utils/scheduler.py", line 125, in is_scheduler_disabled
    frappe.db.get_single_value("System Settings", "enable_scheduler")
  File "apps/frappe/frappe/database/database.py", line 671, in get_single_value
    val = self.query.get_sql(
  File "apps/frappe/frappe/query_builder/utils.py", line 71, in execute_query
    return frappe.db.sql(query, params, *args, **kwargs)  # nosemgrep
  File "apps/frappe/frappe/database/database.py", line 145, in sql
    self.connect()
  File "apps/frappe/frappe/database/database.py", line 76, in connect
    self._conn = self.get_connection()
  File "apps/frappe/frappe/database/mariadb/database.py", line 79, in get_connection
    conn = pymysql.connect(
  File "env/lib/python3.8/site-packages/pymysql/connections.py", line 353, in __init__
    self.connect()
  File "env/lib/python3.8/site-packages/pymysql/connections.py", line 633, in connect
    self._request_authentication()
  File "env/lib/python3.8/site-packages/pymysql/connections.py", line 907, in _request_authentication
    auth_packet = self._read_packet()
  File "env/lib/python3.8/site-packages/pymysql/connections.py", line 725, in _read_packet
    packet.raise_for_error()
  File "env/lib/python3.8/site-packages/pymysql/protocol.py", line 221, in raise_for_error
    err.raise_mysql_exception(self._data)
  File "env/lib/python3.8/site-packages/pymysql/err.py", line 143, in raise_mysql_exception
    raise errorclass(errno, errval)
pymysql.err.OperationalError: (1698, "Access denied for user '_b03d59da10ef7e85'@'localhost'")

2022-05-30 11:42:05,977 ERROR scheduler Exception in Enqueue Events for Site website
Traceback (most recent call last):
  File "apps/frappe/frappe/utils/scheduler.py", line 76, in enqueue_events_for_site
    if is_scheduler_inactive():
  File "apps/frappe/frappe/utils/scheduler.py", line 113, in is_scheduler_inactive
    if is_scheduler_disabled():
  File "apps/frappe/frappe/utils/scheduler.py", line 125, in is_scheduler_disabled
    frappe.db.get_single_value("System Settings", "enable_scheduler")
  File "apps/frappe/frappe/database/database.py", line 671, in get_single_value
    val = self.query.get_sql(
  File "apps/frappe/frappe/query_builder/utils.py", line 71, in execute_query
    return frappe.db.sql(query, params, *args, **kwargs)  # nosemgrep
  File "apps/frappe/frappe/database/database.py", line 145, in sql
    self.connect()
  File "apps/frappe/frappe/database/database.py", line 76, in connect
    self._conn = self.get_connection()
  File "apps/frappe/frappe/database/mariadb/database.py", line 79, in get_connection
    conn = pymysql.connect(
  File "env/lib/python3.8/site-packages/pymysql/connections.py", line 353, in __init__
    self.connect()
  File "env/lib/python3.8/site-packages/pymysql/connections.py", line 633, in connect
    self._request_authentication()
  File "env/lib/python3.8/site-packages/pymysql/connections.py", line 907, in _request_authentication
    auth_packet = self._read_packet()
  File "env/lib/python3.8/site-packages/pymysql/connections.py", line 725, in _read_packet
    packet.raise_for_error()
  File "env/lib/python3.8/site-packages/pymysql/protocol.py", line 221, in raise_for_error
    err.raise_mysql_exception(self._data)
  File "env/lib/python3.8/site-packages/pymysql/err.py", line 143, in raise_mysql_exception
    raise errorclass(errno, errval)
pymysql.err.OperationalError: (1698, "Access denied for user '_b03d59da10ef7e85'@'localhost'")

2022-05-30 11:43:06,169 ERROR scheduler Exception in Enqueue Events for Site website
Traceback (most recent call last):
  File "apps/frappe/frappe/utils/scheduler.py", line 76, in enqueue_events_for_site
    if is_scheduler_inactive():
  File "apps/frappe/frappe/utils/scheduler.py", line 113, in is_scheduler_inactive
    if is_scheduler_disabled():
  File "apps/frappe/frappe/utils/scheduler.py", line 125, in is_scheduler_disabled
    frappe.db.get_single_value("System Settings", "enable_scheduler")
  File "apps/frappe/frappe/database/database.py", line 671, in get_single_value
    val = self.query.get_sql(
  File "apps/frappe/frappe/query_builder/utils.py", line 71, in execute_query
    return frappe.db.sql(query, params, *args, **kwargs)  # nosemgrep
  File "apps/frappe/frappe/database/database.py", line 145, in sql
    self.connect()
  File "apps/frappe/frappe/database/database.py", line 76, in connect
    self._conn = self.get_connection()
  File "apps/frappe/frappe/database/mariadb/database.py", line 79, in get_connection
    conn = pymysql.connect(
  File "env/lib/python3.8/site-packages/pymysql/connections.py", line 353, in __init__
    self.connect()
  File "env/lib/python3.8/site-packages/pymysql/connections.py", line 633, in connect
    self._request_authentication()
  File "env/lib/python3.8/site-packages/pymysql/connections.py", line 907, in _request_authentication
    auth_packet = self._read_packet()
  File "env/lib/python3.8/site-packages/pymysql/connections.py", line 725, in _read_packet
    packet.raise_for_error()
  File "env/lib/python3.8/site-packages/pymysql/protocol.py", line 221, in raise_for_error
    err.raise_mysql_exception(self._data)
  File "env/lib/python3.8/site-packages/pymysql/err.py", line 143, in raise_mysql_exception
    raise errorclass(errno, errval)
pymysql.err.OperationalError: (1698, "Access denied for user '_b03d59da10ef7e85'@'localhost'")

2022-05-30 11:44:06,395 ERROR scheduler Exception in Enqueue Events for Site website
Traceback (most recent call last):
  File "apps/frappe/frappe/utils/scheduler.py", line 76, in enqueue_events_for_site
    if is_scheduler_inactive():
  File "apps/frappe/frappe/utils/scheduler.py", line 113, in is_scheduler_inactive
    if is_scheduler_disabled():
  File "apps/frappe/frappe/utils/scheduler.py", line 125, in is_scheduler_disabled
    frappe.db.get_single_value("System Settings", "enable_scheduler")
  File "apps/frappe/frappe/database/database.py", line 671, in get_single_value
    val = self.query.get_sql(
  File "apps/frappe/frappe/query_builder/utils.py", line 71, in execute_query
    return frappe.db.sql(query, params, *args, **kwargs)  # nosemgrep
  File "apps/frappe/frappe/database/database.py", line 145, in sql
    self.connect()
  File "apps/frappe/frappe/database/database.py", line 76, in connect
    self._conn = self.get_connection()
  File "apps/frappe/frappe/database/mariadb/database.py", line 79, in get_connection
    conn = pymysql.connect(
  File "env/lib/python3.8/site-packages/pymysql/connections.py", line 353, in __init__
    self.connect()
  File "env/lib/python3.8/site-packages/pymysql/connections.py", line 633, in connect
    self._request_authentication()
  File "env/lib/python3.8/site-packages/pymysql/connections.py", line 907, in _request_authentication
    auth_packet = self._read_packet()
  File "env/lib/python3.8/site-packages/pymysql/connections.py", line 725, in _read_packet
    packet.raise_for_error()
  File "env/lib/python3.8/site-packages/pymysql/protocol.py", line 221, in raise_for_error
    err.raise_mysql_exception(self._data)
  File "env/lib/python3.8/site-packages/pymysql/err.py", line 143, in raise_mysql_exception
    raise errorclass(errno, errval)
pymysql.err.OperationalError: (1698, "Access denied for user '_b03d59da10ef7e85'@'localhost'")

2022-05-30 11:45:06,618 ERROR scheduler Exception in Enqueue Events for Site website
Traceback (most recent call last):
  File "apps/frappe/frappe/utils/scheduler.py", line 76, in enqueue_events_for_site
    if is_scheduler_inactive():
  File "apps/frappe/frappe/utils/scheduler.py", line 113, in is_scheduler_inactive
    if is_scheduler_disabled():
  File "apps/frappe/frappe/utils/scheduler.py", line 125, in is_scheduler_disabled
    frappe.db.get_single_value("System Settings", "enable_scheduler")
  File "apps/frappe/frappe/database/database.py", line 671, in get_single_value
    val = self.query.get_sql(
  File "apps/frappe/frappe/query_builder/utils.py", line 71, in execute_query
    return frappe.db.sql(query, params, *args, **kwargs)  # nosemgrep
  File "apps/frappe/frappe/database/database.py", line 145, in sql
    self.connect()
  File "apps/frappe/frappe/database/database.py", line 76, in connect
    self._conn = self.get_connection()
  File "apps/frappe/frappe/database/mariadb/database.py", line 79, in get_connection
    conn = pymysql.connect(
  File "env/lib/python3.8/site-packages/pymysql/connections.py", line 353, in __init__
    self.connect()
  File "env/lib/python3.8/site-packages/pymysql/connections.py", line 633, in connect
    self._request_authentication()
  File "env/lib/python3.8/site-packages/pymysql/connections.py", line 907, in _request_authentication
    auth_packet = self._read_packet()
  File "env/lib/python3.8/site-packages/pymysql/connections.py", line 725, in _read_packet
    packet.raise_for_error()
  File "env/lib/python3.8/site-packages/pymysql/protocol.py", line 221, in raise_for_error
    err.raise_mysql_exception(self._data)
  File "env/lib/python3.8/site-packages/pymysql/err.py", line 143, in raise_mysql_exception
    raise errorclass(errno, errval)
pymysql.err.OperationalError: (1698, "Access denied for user '_b03d59da10ef7e85'@'localhost'")

2022-05-30 11:46:06,809 ERROR scheduler Exception in Enqueue Events for Site website
Traceback (most recent call last):
  File "apps/frappe/frappe/utils/scheduler.py", line 76, in enqueue_events_for_site
    if is_scheduler_inactive():
  File "apps/frappe/frappe/utils/scheduler.py", line 113, in is_scheduler_inactive
    if is_scheduler_disabled():
  File "apps/frappe/frappe/utils/scheduler.py", line 125, in is_scheduler_disabled
    frappe.db.get_single_value("System Settings", "enable_scheduler")
  File "apps/frappe/frappe/database/database.py", line 671, in get_single_value
    val = self.query.get_sql(
  File "apps/frappe/frappe/query_builder/utils.py", line 71, in execute_query
    return frappe.db.sql(query, params, *args, **kwargs)  # nosemgrep
  File "apps/frappe/frappe/database/database.py", line 145, in sql
    self.connect()
  File "apps/frappe/frappe/database/database.py", line 76, in connect
    self._conn = self.get_connection()
  File "apps/frappe/frappe/database/mariadb/database.py", line 79, in get_connection
    conn = pymysql.connect(
  File "env/lib/python3.8/site-packages/pymysql/connections.py", line 353, in __init__
    self.connect()
  File "env/lib/python3.8/site-packages/pymysql/connections.py", line 633, in connect
    self._request_authentication()
  File "env/lib/python3.8/site-packages/pymysql/connections.py", line 907, in _request_authentication
    auth_packet = self._read_packet()
  File "env/lib/python3.8/site-packages/pymysql/connections.py", line 725, in _read_packet
    packet.raise_for_error()
  File "env/lib/python3.8/site-packages/pymysql/protocol.py", line 221, in raise_for_error
    err.raise_mysql_exception(self._data)
  File "env/lib/python3.8/site-packages/pymysql/err.py", line 143, in raise_mysql_exception
    raise errorclass(errno, errval)
pymysql.err.OperationalError: (1698, "Access denied for user '_b03d59da10ef7e85'@'localhost'")

2022-05-30 11:47:06,997 ERROR scheduler Exception in Enqueue Events for Site website
Traceback (most recent call last):
  File "apps/frappe/frappe/utils/scheduler.py", line 76, in enqueue_events_for_site
    if is_scheduler_inactive():
  File "apps/frappe/frappe/utils/scheduler.py", line 113, in is_scheduler_inactive
    if is_scheduler_disabled():
  File "apps/frappe/frappe/utils/scheduler.py", line 125, in is_scheduler_disabled
    frappe.db.get_single_value("System Settings", "enable_scheduler")
  File "apps/frappe/frappe/database/database.py", line 671, in get_single_value
    val = self.query.get_sql(
  File "apps/frappe/frappe/query_builder/utils.py", line 71, in execute_query
    return frappe.db.sql(query, params, *args, **kwargs)  # nosemgrep
  File "apps/frappe/frappe/database/database.py", line 145, in sql
    self.connect()
  File "apps/frappe/frappe/database/database.py", line 76, in connect
    self._conn = self.get_connection()
  File "apps/frappe/frappe/database/mariadb/database.py", line 79, in get_connection
    conn = pymysql.connect(
  File "env/lib/python3.8/site-packages/pymysql/connections.py", line 353, in __init__
    self.connect()
  File "env/lib/python3.8/site-packages/pymysql/connections.py", line 633, in connect
    self._request_authentication()
  File "env/lib/python3.8/site-packages/pymysql/connections.py", line 907, in _request_authentication
    auth_packet = self._read_packet()
  File "env/lib/python3.8/site-packages/pymysql/connections.py", line 725, in _read_packet
    packet.raise_for_error()
  File "env/lib/python3.8/site-packages/pymysql/protocol.py", line 221, in raise_for_error
    err.raise_mysql_exception(self._data)
  File "env/lib/python3.8/site-packages/pymysql/err.py", line 143, in raise_mysql_exception
    raise errorclass(errno, errval)
pymysql.err.OperationalError: (1698, "Access denied for user '_b03d59da10ef7e85'@'localhost'")

2022-05-30 11:48:07,217 ERROR scheduler Exception in Enqueue Events for Site website
Traceback (most recent call last):
  File "apps/frappe/frappe/utils/scheduler.py", line 76, in enqueue_events_for_site
    if is_scheduler_inactive():
  File "apps/frappe/frappe/utils/scheduler.py", line 113, in is_scheduler_inactive
    if is_scheduler_disabled():
  File "apps/frappe/frappe/utils/scheduler.py", line 125, in is_scheduler_disabled
    frappe.db.get_single_value("System Settings", "enable_scheduler")
  File "apps/frappe/frappe/database/database.py", line 671, in get_single_value
    val = self.query.get_sql(
  File "apps/frappe/frappe/query_builder/utils.py", line 71, in execute_query
    return frappe.db.sql(query, params, *args, **kwargs)  # nosemgrep
  File "apps/frappe/frappe/database/database.py", line 145, in sql
    self.connect()
  File "apps/frappe/frappe/database/database.py", line 76, in connect
    self._conn = self.get_connection()
  File "apps/frappe/frappe/database/mariadb/database.py", line 79, in get_connection
    conn = pymysql.connect(
  File "env/lib/python3.8/site-packages/pymysql/connections.py", line 353, in __init__
    self.connect()
  File "env/lib/python3.8/site-packages/pymysql/connections.py", line 633, in connect
    self._request_authentication()
  File "env/lib/python3.8/site-packages/pymysql/connections.py", line 907, in _request_authentication
    auth_packet = self._read_packet()
  File "env/lib/python3.8/site-packages/pymysql/connections.py", line 725, in _read_packet
    packet.raise_for_error()
  File "env/lib/python3.8/site-packages/pymysql/protocol.py", line 221, in raise_for_error
    err.raise_mysql_exception(self._data)
  File "env/lib/python3.8/site-packages/pymysql/err.py", line 143, in raise_mysql_exception
    raise errorclass(errno, errval)
pymysql.err.OperationalError: (1698, "Access denied for user '_b03d59da10ef7e85'@'localhost'")

2022-05-30 11:49:07,368 ERROR scheduler Exception in Enqueue Events for Site website
Traceback (most recent call last):
  File "apps/frappe/frappe/utils/scheduler.py", line 76, in enqueue_events_for_site
    if is_scheduler_inactive():
  File "apps/frappe/frappe/utils/scheduler.py", line 113, in is_scheduler_inactive
    if is_scheduler_disabled():
  File "apps/frappe/frappe/utils/scheduler.py", line 125, in is_scheduler_disabled
    frappe.db.get_single_value("System Settings", "enable_scheduler")
  File "apps/frappe/frappe/database/database.py", line 671, in get_single_value
    val = self.query.get_sql(
  File "apps/frappe/frappe/query_builder/utils.py", line 71, in execute_query
    return frappe.db.sql(query, params, *args, **kwargs)  # nosemgrep
  File "apps/frappe/frappe/database/database.py", line 145, in sql
    self.connect()
  File "apps/frappe/frappe/database/database.py", line 76, in connect
    self._conn = self.get_connection()
  File "apps/frappe/frappe/database/mariadb/database.py", line 79, in get_connection
    conn = pymysql.connect(
  File "env/lib/python3.8/site-packages/pymysql/connections.py", line 353, in __init__
    self.connect()
  File "env/lib/python3.8/site-packages/pymysql/connections.py", line 633, in connect
    self._request_authentication()
  File "env/lib/python3.8/site-packages/pymysql/connections.py", line 907, in _request_authentication
    auth_packet = self._read_packet()
  File "env/lib/python3.8/site-packages/pymysql/connections.py", line 725, in _read_packet
    packet.raise_for_error()
  File "env/lib/python3.8/site-packages/pymysql/protocol.py", line 221, in raise_for_error
    err.raise_mysql_exception(self._data)
  File "env/lib/python3.8/site-packages/pymysql/err.py", line 143, in raise_mysql_exception
    raise errorclass(errno, errval)
pymysql.err.OperationalError: (1698, "Access denied for user '_b03d59da10ef7e85'@'localhost'")

2022-05-30 11:50:07,559 ERROR scheduler Exception in Enqueue Events for Site website
Traceback (most recent call last):
  File "apps/frappe/frappe/utils/scheduler.py", line 76, in enqueue_events_for_site
    if is_scheduler_inactive():
  File "apps/frappe/frappe/utils/scheduler.py", line 113, in is_scheduler_inactive
    if is_scheduler_disabled():
  File "apps/frappe/frappe/utils/scheduler.py", line 125, in is_scheduler_disabled
    frappe.db.get_single_value("System Settings", "enable_scheduler")
  File "apps/frappe/frappe/database/database.py", line 671, in get_single_value
    val = self.query.get_sql(
  File "apps/frappe/frappe/query_builder/utils.py", line 71, in execute_query
    return frappe.db.sql(query, params, *args, **kwargs)  # nosemgrep
  File "apps/frappe/frappe/database/database.py", line 145, in sql
    self.connect()
  File "apps/frappe/frappe/database/database.py", line 76, in connect
    self._conn = self.get_connection()
  File "apps/frappe/frappe/database/mariadb/database.py", line 79, in get_connection
    conn = pymysql.connect(
  File "env/lib/python3.8/site-packages/pymysql/connections.py", line 353, in __init__
    self.connect()
  File "env/lib/python3.8/site-packages/pymysql/connections.py", line 633, in connect
    self._request_authentication()
  File "env/lib/python3.8/site-packages/pymysql/connections.py", line 907, in _request_authentication
    auth_packet = self._read_packet()
  File "env/lib/python3.8/site-packages/pymysql/connections.py", line 725, in _read_packet
    packet.raise_for_error()
  File "env/lib/python3.8/site-packages/pymysql/protocol.py", line 221, in raise_for_error
    err.raise_mysql_exception(self._data)
  File "env/lib/python3.8/site-packages/pymysql/err.py", line 143, in raise_mysql_exception
    raise errorclass(errno, errval)
pymysql.err.OperationalError: (1698, "Access denied for user '_b03d59da10ef7e85'@'localhost'")

2022-05-30 11:51:07,731 ERROR scheduler Exception in Enqueue Events for Site website
Traceback (most recent call last):
  File "apps/frappe/frappe/utils/scheduler.py", line 76, in enqueue_events_for_site
    if is_scheduler_inactive():
  File "apps/frappe/frappe/utils/scheduler.py", line 113, in is_scheduler_inactive
    if is_scheduler_disabled():
  File "apps/frappe/frappe/utils/scheduler.py", line 125, in is_scheduler_disabled
    frappe.db.get_single_value("System Settings", "enable_scheduler")
  File "apps/frappe/frappe/database/database.py", line 671, in get_single_value
    val = self.query.get_sql(
  File "apps/frappe/frappe/query_builder/utils.py", line 71, in execute_query
    return frappe.db.sql(query, params, *args, **kwargs)  # nosemgrep
  File "apps/frappe/frappe/database/database.py", line 145, in sql
    self.connect()
  File "apps/frappe/frappe/database/database.py", line 76, in connect
    self._conn = self.get_connection()
  File "apps/frappe/frappe/database/mariadb/database.py", line 79, in get_connection
    conn = pymysql.connect(
  File "env/lib/python3.8/site-packages/pymysql/connections.py", line 353, in __init__
    self.connect()
  File "env/lib/python3.8/site-packages/pymysql/connections.py", line 633, in connect
    self._request_authentication()
  File "env/lib/python3.8/site-packages/pymysql/connections.py", line 907, in _request_authentication
    auth_packet = self._read_packet()
  File "env/lib/python3.8/site-packages/pymysql/connections.py", line 725, in _read_packet
    packet.raise_for_error()
  File "env/lib/python3.8/site-packages/pymysql/protocol.py", line 221, in raise_for_error
    err.raise_mysql_exception(self._data)
  File "env/lib/python3.8/site-packages/pymysql/err.py", line 143, in raise_mysql_exception
    raise errorclass(errno, errval)
pymysql.err.OperationalError: (1698, "Access denied for user '_b03d59da10ef7e85'@'localhost'")

2022-05-30 11:52:07,951 ERROR scheduler Exception in Enqueue Events for Site website
Traceback (most recent call last):
  File "apps/frappe/frappe/utils/scheduler.py", line 76, in enqueue_events_for_site
    if is_scheduler_inactive():
  File "apps/frappe/frappe/utils/scheduler.py", line 113, in is_scheduler_inactive
    if is_scheduler_disabled():
  File "apps/frappe/frappe/utils/scheduler.py", line 125, in is_scheduler_disabled
    frappe.db.get_single_value("System Settings", "enable_scheduler")
  File "apps/frappe/frappe/database/database.py", line 671, in get_single_value
    val = self.query.get_sql(
  File "apps/frappe/frappe/query_builder/utils.py", line 71, in execute_query
    return frappe.db.sql(query, params, *args, **kwargs)  # nosemgrep
  File "apps/frappe/frappe/database/database.py", line 145, in sql
    self.connect()
  File "apps/frappe/frappe/database/database.py", line 76, in connect
    self._conn = self.get_connection()
  File "apps/frappe/frappe/database/mariadb/database.py", line 79, in get_connection
    conn = pymysql.connect(
  File "env/lib/python3.8/site-packages/pymysql/connections.py", line 353, in __init__
    self.connect()
  File "env/lib/python3.8/site-packages/pymysql/connections.py", line 633, in connect
    self._request_authentication()
  File "env/lib/python3.8/site-packages/pymysql/connections.py", line 907, in _request_authentication
    auth_packet = self._read_packet()
  File "env/lib/python3.8/site-packages/pymysql/connections.py", line 725, in _read_packet
    packet.raise_for_error()
  File "env/lib/python3.8/site-packages/pymysql/protocol.py", line 221, in raise_for_error
    err.raise_mysql_exception(self._data)
  File "env/lib/python3.8/site-packages/pymysql/err.py", line 143, in raise_mysql_exception
    raise errorclass(errno, errval)
pymysql.err.OperationalError: (1698, "Access denied for user '_b03d59da10ef7e85'@'localhost'")

2022-05-30 11:53:08,110 ERROR scheduler Exception in Enqueue Events for Site website
Traceback (most recent call last):
  File "apps/frappe/frappe/utils/scheduler.py", line 76, in enqueue_events_for_site
    if is_scheduler_inactive():
  File "apps/frappe/frappe/utils/scheduler.py", line 113, in is_scheduler_inactive
    if is_scheduler_disabled():
  File "apps/frappe/frappe/utils/scheduler.py", line 125, in is_scheduler_disabled
    frappe.db.get_single_value("System Settings", "enable_scheduler")
  File "apps/frappe/frappe/database/database.py", line 671, in get_single_value
    val = self.query.get_sql(
  File "apps/frappe/frappe/query_builder/utils.py", line 71, in execute_query
    return frappe.db.sql(query, params, *args, **kwargs)  # nosemgrep
  File "apps/frappe/frappe/database/database.py", line 145, in sql
    self.connect()
  File "apps/frappe/frappe/database/database.py", line 76, in connect
    self._conn = self.get_connection()
  File "apps/frappe/frappe/database/mariadb/database.py", line 79, in get_connection
    conn = pymysql.connect(
  File "env/lib/python3.8/site-packages/pymysql/connections.py", line 353, in __init__
    self.connect()
  File "env/lib/python3.8/site-packages/pymysql/connections.py", line 633, in connect
    self._request_authentication()
  File "env/lib/python3.8/site-packages/pymysql/connections.py", line 907, in _request_authentication
    auth_packet = self._read_packet()
  File "env/lib/python3.8/site-packages/pymysql/connections.py", line 725, in _read_packet
    packet.raise_for_error()
  File "env/lib/python3.8/site-packages/pymysql/protocol.py", line 221, in raise_for_error
    err.raise_mysql_exception(self._data)
  File "env/lib/python3.8/site-packages/pymysql/err.py", line 143, in raise_mysql_exception
    raise errorclass(errno, errval)
pymysql.err.OperationalError: (1698, "Access denied for user '_b03d59da10ef7e85'@'localhost'")

2022-05-30 11:54:08,305 ERROR scheduler Exception in Enqueue Events for Site website
Traceback (most recent call last):
  File "apps/frappe/frappe/utils/scheduler.py", line 76, in enqueue_events_for_site
    if is_scheduler_inactive():
  File "apps/frappe/frappe/utils/scheduler.py", line 113, in is_scheduler_inactive
    if is_scheduler_disabled():
  File "apps/frappe/frappe/utils/scheduler.py", line 125, in is_scheduler_disabled
    frappe.db.get_single_value("System Settings", "enable_scheduler")
  File "apps/frappe/frappe/database/database.py", line 671, in get_single_value
    val = self.query.get_sql(
  File "apps/frappe/frappe/query_builder/utils.py", line 71, in execute_query
    return frappe.db.sql(query, params, *args, **kwargs)  # nosemgrep
  File "apps/frappe/frappe/database/database.py", line 145, in sql
    self.connect()
  File "apps/frappe/frappe/database/database.py", line 76, in connect
    self._conn = self.get_connection()
  File "apps/frappe/frappe/database/mariadb/database.py", line 79, in get_connection
    conn = pymysql.connect(
  File "env/lib/python3.8/site-packages/pymysql/connections.py", line 353, in __init__
    self.connect()
  File "env/lib/python3.8/site-packages/pymysql/connections.py", line 633, in connect
    self._request_authentication()
  File "env/lib/python3.8/site-packages/pymysql/connections.py", line 907, in _request_authentication
    auth_packet = self._read_packet()
  File "env/lib/python3.8/site-packages/pymysql/connections.py", line 725, in _read_packet
    packet.raise_for_error()
  File "env/lib/python3.8/site-packages/pymysql/protocol.py", line 221, in raise_for_error
    err.raise_mysql_exception(self._data)
  File "env/lib/python3.8/site-packages/pymysql/err.py", line 143, in raise_mysql_exception
    raise errorclass(errno, errval)
pymysql.err.OperationalError: (1698, "Access denied for user '_b03d59da10ef7e85'@'localhost'")

2022-05-30 11:55:08,503 ERROR scheduler Exception in Enqueue Events for Site website
Traceback (most recent call last):
  File "apps/frappe/frappe/utils/scheduler.py", line 76, in enqueue_events_for_site
    if is_scheduler_inactive():
  File "apps/frappe/frappe/utils/scheduler.py", line 113, in is_scheduler_inactive
    if is_scheduler_disabled():
  File "apps/frappe/frappe/utils/scheduler.py", line 125, in is_scheduler_disabled
    frappe.db.get_single_value("System Settings", "enable_scheduler")
  File "apps/frappe/frappe/database/database.py", line 671, in get_single_value
    val = self.query.get_sql(
  File "apps/frappe/frappe/query_builder/utils.py", line 71, in execute_query
    return frappe.db.sql(query, params, *args, **kwargs)  # nosemgrep
  File "apps/frappe/frappe/database/database.py", line 145, in sql
    self.connect()
  File "apps/frappe/frappe/database/database.py", line 76, in connect
    self._conn = self.get_connection()
  File "apps/frappe/frappe/database/mariadb/database.py", line 79, in get_connection
    conn = pymysql.connect(
  File "env/lib/python3.8/site-packages/pymysql/connections.py", line 353, in __init__
    self.connect()
  File "env/lib/python3.8/site-packages/pymysql/connections.py", line 633, in connect
    self._request_authentication()
  File "env/lib/python3.8/site-packages/pymysql/connections.py", line 907, in _request_authentication
    auth_packet = self._read_packet()
  File "env/lib/python3.8/site-packages/pymysql/connections.py", line 725, in _read_packet
    packet.raise_for_error()
  File "env/lib/python3.8/site-packages/pymysql/protocol.py", line 221, in raise_for_error
    err.raise_mysql_exception(self._data)
  File "env/lib/python3.8/site-packages/pymysql/err.py", line 143, in raise_mysql_exception
    raise errorclass(errno, errval)
pymysql.err.OperationalError: (1698, "Access denied for user '_b03d59da10ef7e85'@'localhost'")

2022-05-30 11:56:08,732 ERROR scheduler Exception in Enqueue Events for Site website
Traceback (most recent call last):
  File "apps/frappe/frappe/utils/scheduler.py", line 76, in enqueue_events_for_site
    if is_scheduler_inactive():
  File "apps/frappe/frappe/utils/scheduler.py", line 113, in is_scheduler_inactive
    if is_scheduler_disabled():
  File "apps/frappe/frappe/utils/scheduler.py", line 125, in is_scheduler_disabled
    frappe.db.get_single_value("System Settings", "enable_scheduler")
  File "apps/frappe/frappe/database/database.py", line 671, in get_single_value
    val = self.query.get_sql(
  File "apps/frappe/frappe/query_builder/utils.py", line 71, in execute_query
    return frappe.db.sql(query, params, *args, **kwargs)  # nosemgrep
  File "apps/frappe/frappe/database/database.py", line 145, in sql
    self.connect()
  File "apps/frappe/frappe/database/database.py", line 76, in connect
    self._conn = self.get_connection()
  File "apps/frappe/frappe/database/mariadb/database.py", line 79, in get_connection
    conn = pymysql.connect(
  File "env/lib/python3.8/site-packages/pymysql/connections.py", line 353, in __init__
    self.connect()
  File "env/lib/python3.8/site-packages/pymysql/connections.py", line 633, in connect
    self._request_authentication()
  File "env/lib/python3.8/site-packages/pymysql/connections.py", line 907, in _request_authentication
    auth_packet = self._read_packet()
  File "env/lib/python3.8/site-packages/pymysql/connections.py", line 725, in _read_packet
    packet.raise_for_error()
  File "env/lib/python3.8/site-packages/pymysql/protocol.py", line 221, in raise_for_error
    err.raise_mysql_exception(self._data)
  File "env/lib/python3.8/site-packages/pymysql/err.py", line 143, in raise_mysql_exception
    raise errorclass(errno, errval)
pymysql.err.OperationalError: (1698, "Access denied for user '_b03d59da10ef7e85'@'localhost'")

2022-05-30 11:57:08,926 ERROR scheduler Exception in Enqueue Events for Site website
Traceback (most recent call last):
  File "apps/frappe/frappe/utils/scheduler.py", line 76, in enqueue_events_for_site
    if is_scheduler_inactive():
  File "apps/frappe/frappe/utils/scheduler.py", line 113, in is_scheduler_inactive
    if is_scheduler_disabled():
  File "apps/frappe/frappe/utils/scheduler.py", line 125, in is_scheduler_disabled
    frappe.db.get_single_value("System Settings", "enable_scheduler")
  File "apps/frappe/frappe/database/database.py", line 671, in get_single_value
    val = self.query.get_sql(
  File "apps/frappe/frappe/query_builder/utils.py", line 71, in execute_query
    return frappe.db.sql(query, params, *args, **kwargs)  # nosemgrep
  File "apps/frappe/frappe/database/database.py", line 145, in sql
    self.connect()
  File "apps/frappe/frappe/database/database.py", line 76, in connect
    self._conn = self.get_connection()
  File "apps/frappe/frappe/database/mariadb/database.py", line 79, in get_connection
    conn = pymysql.connect(
  File "env/lib/python3.8/site-packages/pymysql/connections.py", line 353, in __init__
    self.connect()
  File "env/lib/python3.8/site-packages/pymysql/connections.py", line 633, in connect
    self._request_authentication()
  File "env/lib/python3.8/site-packages/pymysql/connections.py", line 907, in _request_authentication
    auth_packet = self._read_packet()
  File "env/lib/python3.8/site-packages/pymysql/connections.py", line 725, in _read_packet
    packet.raise_for_error()
  File "env/lib/python3.8/site-packages/pymysql/protocol.py", line 221, in raise_for_error
    err.raise_mysql_exception(self._data)
  File "env/lib/python3.8/site-packages/pymysql/err.py", line 143, in raise_mysql_exception
    raise errorclass(errno, errval)
pymysql.err.OperationalError: (1698, "Access denied for user '_b03d59da10ef7e85'@'localhost'")

2022-05-30 11:58:09,078 ERROR scheduler Exception in Enqueue Events for Site website
Traceback (most recent call last):
  File "apps/frappe/frappe/utils/scheduler.py", line 76, in enqueue_events_for_site
    if is_scheduler_inactive():
  File "apps/frappe/frappe/utils/scheduler.py", line 113, in is_scheduler_inactive
    if is_scheduler_disabled():
  File "apps/frappe/frappe/utils/scheduler.py", line 125, in is_scheduler_disabled
    frappe.db.get_single_value("System Settings", "enable_scheduler")
  File "apps/frappe/frappe/database/database.py", line 671, in get_single_value
    val = self.query.get_sql(
  File "apps/frappe/frappe/query_builder/utils.py", line 71, in execute_query
    return frappe.db.sql(query, params, *args, **kwargs)  # nosemgrep
  File "apps/frappe/frappe/database/database.py", line 145, in sql
    self.connect()
  File "apps/frappe/frappe/database/database.py", line 76, in connect
    self._conn = self.get_connection()
  File "apps/frappe/frappe/database/mariadb/database.py", line 79, in get_connection
    conn = pymysql.connect(
  File "env/lib/python3.8/site-packages/pymysql/connections.py", line 353, in __init__
    self.connect()
  File "env/lib/python3.8/site-packages/pymysql/connections.py", line 633, in connect
    self._request_authentication()
  File "env/lib/python3.8/site-packages/pymysql/connections.py", line 907, in _request_authentication
    auth_packet = self._read_packet()
  File "env/lib/python3.8/site-packages/pymysql/connections.py", line 725, in _read_packet
    packet.raise_for_error()
  File "env/lib/python3.8/site-packages/pymysql/protocol.py", line 221, in raise_for_error
    err.raise_mysql_exception(self._data)
  File "env/lib/python3.8/site-packages/pymysql/err.py", line 143, in raise_mysql_exception
    raise errorclass(errno, errval)
pymysql.err.OperationalError: (1698, "Access denied for user '_b03d59da10ef7e85'@'localhost'")

2022-05-30 11:59:09,271 ERROR scheduler Exception in Enqueue Events for Site website
Traceback (most recent call last):
  File "apps/frappe/frappe/utils/scheduler.py", line 76, in enqueue_events_for_site
    if is_scheduler_inactive():
  File "apps/frappe/frappe/utils/scheduler.py", line 113, in is_scheduler_inactive
    if is_scheduler_disabled():
  File "apps/frappe/frappe/utils/scheduler.py", line 125, in is_scheduler_disabled
    frappe.db.get_single_value("System Settings", "enable_scheduler")
  File "apps/frappe/frappe/database/database.py", line 671, in get_single_value
    val = self.query.get_sql(
  File "apps/frappe/frappe/query_builder/utils.py", line 71, in execute_query
    return frappe.db.sql(query, params, *args, **kwargs)  # nosemgrep
  File "apps/frappe/frappe/database/database.py", line 145, in sql
    self.connect()
  File "apps/frappe/frappe/database/database.py", line 76, in connect
    self._conn = self.get_connection()
  File "apps/frappe/frappe/database/mariadb/database.py", line 79, in get_connection
    conn = pymysql.connect(
  File "env/lib/python3.8/site-packages/pymysql/connections.py", line 353, in __init__
    self.connect()
  File "env/lib/python3.8/site-packages/pymysql/connections.py", line 633, in connect
    self._request_authentication()
  File "env/lib/python3.8/site-packages/pymysql/connections.py", line 907, in _request_authentication
    auth_packet = self._read_packet()
  File "env/lib/python3.8/site-packages/pymysql/connections.py", line 725, in _read_packet
    packet.raise_for_error()
  File "env/lib/python3.8/site-packages/pymysql/protocol.py", line 221, in raise_for_error
    err.raise_mysql_exception(self._data)
  File "env/lib/python3.8/site-packages/pymysql/err.py", line 143, in raise_mysql_exception
    raise errorclass(errno, errval)
pymysql.err.OperationalError: (1698, "Access denied for user '_b03d59da10ef7e85'@'localhost'")

2022-05-30 12:00:09,575 ERROR scheduler Exception in Enqueue Events for Site website
Traceback (most recent call last):
  File "apps/frappe/frappe/utils/scheduler.py", line 76, in enqueue_events_for_site
    if is_scheduler_inactive():
  File "apps/frappe/frappe/utils/scheduler.py", line 113, in is_scheduler_inactive
    if is_scheduler_disabled():
  File "apps/frappe/frappe/utils/scheduler.py", line 125, in is_scheduler_disabled
    frappe.db.get_single_value("System Settings", "enable_scheduler")
  File "apps/frappe/frappe/database/database.py", line 671, in get_single_value
    val = self.query.get_sql(
  File "apps/frappe/frappe/query_builder/utils.py", line 71, in execute_query
    return frappe.db.sql(query, params, *args, **kwargs)  # nosemgrep
  File "apps/frappe/frappe/database/database.py", line 145, in sql
    self.connect()
  File "apps/frappe/frappe/database/database.py", line 76, in connect
    self._conn = self.get_connection()
  File "apps/frappe/frappe/database/mariadb/database.py", line 79, in get_connection
    conn = pymysql.connect(
  File "env/lib/python3.8/site-packages/pymysql/connections.py", line 353, in __init__
    self.connect()
  File "env/lib/python3.8/site-packages/pymysql/connections.py", line 633, in connect
    self._request_authentication()
  File "env/lib/python3.8/site-packages/pymysql/connections.py", line 907, in _request_authentication
    auth_packet = self._read_packet()
  File "env/lib/python3.8/site-packages/pymysql/connections.py", line 725, in _read_packet
    packet.raise_for_error()
  File "env/lib/python3.8/site-packages/pymysql/protocol.py", line 221, in raise_for_error
    err.raise_mysql_exception(self._data)
  File "env/lib/python3.8/site-packages/pymysql/err.py", line 143, in raise_mysql_exception
    raise errorclass(errno, errval)
pymysql.err.OperationalError: (1698, "Access denied for user '_b03d59da10ef7e85'@'localhost'")

2022-05-30 12:01:09,764 ERROR scheduler Exception in Enqueue Events for Site website
Traceback (most recent call last):
  File "apps/frappe/frappe/utils/scheduler.py", line 76, in enqueue_events_for_site
    if is_scheduler_inactive():
  File "apps/frappe/frappe/utils/scheduler.py", line 113, in is_scheduler_inactive
    if is_scheduler_disabled():
  File "apps/frappe/frappe/utils/scheduler.py", line 125, in is_scheduler_disabled
    frappe.db.get_single_value("System Settings", "enable_scheduler")
  File "apps/frappe/frappe/database/database.py", line 671, in get_single_value
    val = self.query.get_sql(
  File "apps/frappe/frappe/query_builder/utils.py", line 71, in execute_query
    return frappe.db.sql(query, params, *args, **kwargs)  # nosemgrep
  File "apps/frappe/frappe/database/database.py", line 145, in sql
    self.connect()
  File "apps/frappe/frappe/database/database.py", line 76, in connect
    self._conn = self.get_connection()
  File "apps/frappe/frappe/database/mariadb/database.py", line 79, in get_connection
    conn = pymysql.connect(
  File "env/lib/python3.8/site-packages/pymysql/connections.py", line 353, in __init__
    self.connect()
  File "env/lib/python3.8/site-packages/pymysql/connections.py", line 633, in connect
    self._request_authentication()
  File "env/lib/python3.8/site-packages/pymysql/connections.py", line 907, in _request_authentication
    auth_packet = self._read_packet()
  File "env/lib/python3.8/site-packages/pymysql/connections.py", line 725, in _read_packet
    packet.raise_for_error()
  File "env/lib/python3.8/site-packages/pymysql/protocol.py", line 221, in raise_for_error
    err.raise_mysql_exception(self._data)
  File "env/lib/python3.8/site-packages/pymysql/err.py", line 143, in raise_mysql_exception
    raise errorclass(errno, errval)
pymysql.err.OperationalError: (1698, "Access denied for user '_b03d59da10ef7e85'@'localhost'")

2022-05-30 12:02:09,945 ERROR scheduler Exception in Enqueue Events for Site website
Traceback (most recent call last):
  File "apps/frappe/frappe/utils/scheduler.py", line 76, in enqueue_events_for_site
    if is_scheduler_inactive():
  File "apps/frappe/frappe/utils/scheduler.py", line 113, in is_scheduler_inactive
    if is_scheduler_disabled():
  File "apps/frappe/frappe/utils/scheduler.py", line 125, in is_scheduler_disabled
    frappe.db.get_single_value("System Settings", "enable_scheduler")
  File "apps/frappe/frappe/database/database.py", line 671, in get_single_value
    val = self.query.get_sql(
  File "apps/frappe/frappe/query_builder/utils.py", line 71, in execute_query
    return frappe.db.sql(query, params, *args, **kwargs)  # nosemgrep
  File "apps/frappe/frappe/database/database.py", line 145, in sql
    self.connect()
  File "apps/frappe/frappe/database/database.py", line 76, in connect
    self._conn = self.get_connection()
  File "apps/frappe/frappe/database/mariadb/database.py", line 79, in get_connection
    conn = pymysql.connect(
  File "env/lib/python3.8/site-packages/pymysql/connections.py", line 353, in __init__
    self.connect()
  File "env/lib/python3.8/site-packages/pymysql/connections.py", line 633, in connect
    self._request_authentication()
  File "env/lib/python3.8/site-packages/pymysql/connections.py", line 907, in _request_authentication
    auth_packet = self._read_packet()
  File "env/lib/python3.8/site-packages/pymysql/connections.py", line 725, in _read_packet
    packet.raise_for_error()
  File "env/lib/python3.8/site-packages/pymysql/protocol.py", line 221, in raise_for_error
    err.raise_mysql_exception(self._data)
  File "env/lib/python3.8/site-packages/pymysql/err.py", line 143, in raise_mysql_exception
    raise errorclass(errno, errval)
pymysql.err.OperationalError: (1698, "Access denied for user '_b03d59da10ef7e85'@'localhost'")

2022-05-30 12:03:10,134 ERROR scheduler Exception in Enqueue Events for Site website
Traceback (most recent call last):
  File "apps/frappe/frappe/utils/scheduler.py", line 76, in enqueue_events_for_site
    if is_scheduler_inactive():
  File "apps/frappe/frappe/utils/scheduler.py", line 113, in is_scheduler_inactive
    if is_scheduler_disabled():
  File "apps/frappe/frappe/utils/scheduler.py", line 125, in is_scheduler_disabled
    frappe.db.get_single_value("System Settings", "enable_scheduler")
  File "apps/frappe/frappe/database/database.py", line 671, in get_single_value
    val = self.query.get_sql(
  File "apps/frappe/frappe/query_builder/utils.py", line 71, in execute_query
    return frappe.db.sql(query, params, *args, **kwargs)  # nosemgrep
  File "apps/frappe/frappe/database/database.py", line 145, in sql
    self.connect()
  File "apps/frappe/frappe/database/database.py", line 76, in connect
    self._conn = self.get_connection()
  File "apps/frappe/frappe/database/mariadb/database.py", line 79, in get_connection
    conn = pymysql.connect(
  File "env/lib/python3.8/site-packages/pymysql/connections.py", line 353, in __init__
    self.connect()
  File "env/lib/python3.8/site-packages/pymysql/connections.py", line 633, in connect
    self._request_authentication()
  File "env/lib/python3.8/site-packages/pymysql/connections.py", line 907, in _request_authentication
    auth_packet = self._read_packet()
  File "env/lib/python3.8/site-packages/pymysql/connections.py", line 725, in _read_packet
    packet.raise_for_error()
  File "env/lib/python3.8/site-packages/pymysql/protocol.py", line 221, in raise_for_error
    err.raise_mysql_exception(self._data)
  File "env/lib/python3.8/site-packages/pymysql/err.py", line 143, in raise_mysql_exception
    raise errorclass(errno, errval)
pymysql.err.OperationalError: (1698, "Access denied for user '_b03d59da10ef7e85'@'localhost'")

2022-05-30 12:04:10,350 ERROR scheduler Exception in Enqueue Events for Site website
Traceback (most recent call last):
  File "apps/frappe/frappe/utils/scheduler.py", line 76, in enqueue_events_for_site
    if is_scheduler_inactive():
  File "apps/frappe/frappe/utils/scheduler.py", line 113, in is_scheduler_inactive
    if is_scheduler_disabled():
  File "apps/frappe/frappe/utils/scheduler.py", line 125, in is_scheduler_disabled
    frappe.db.get_single_value("System Settings", "enable_scheduler")
  File "apps/frappe/frappe/database/database.py", line 671, in get_single_value
    val = self.query.get_sql(
  File "apps/frappe/frappe/query_builder/utils.py", line 71, in execute_query
    return frappe.db.sql(query, params, *args, **kwargs)  # nosemgrep
  File "apps/frappe/frappe/database/database.py", line 145, in sql
    self.connect()
  File "apps/frappe/frappe/database/database.py", line 76, in connect
    self._conn = self.get_connection()
  File "apps/frappe/frappe/database/mariadb/database.py", line 79, in get_connection
    conn = pymysql.connect(
  File "env/lib/python3.8/site-packages/pymysql/connections.py", line 353, in __init__
    self.connect()
  File "env/lib/python3.8/site-packages/pymysql/connections.py", line 633, in connect
    self._request_authentication()
  File "env/lib/python3.8/site-packages/pymysql/connections.py", line 907, in _request_authentication
    auth_packet = self._read_packet()
  File "env/lib/python3.8/site-packages/pymysql/connections.py", line 725, in _read_packet
    packet.raise_for_error()
  File "env/lib/python3.8/site-packages/pymysql/protocol.py", line 221, in raise_for_error
    err.raise_mysql_exception(self._data)
  File "env/lib/python3.8/site-packages/pymysql/err.py", line 143, in raise_mysql_exception
    raise errorclass(errno, errval)
pymysql.err.OperationalError: (1698, "Access denied for user '_b03d59da10ef7e85'@'localhost'")

